Workbook

Sheet Dashboard
A1: BROADCOM / VMWARE M&A MODEL — DASHBOARD
A2: $69bn deal | Closed Oct 2023 | Analyst: Yassin Al-Yassin | March 2026
A4: DEAL SUMMARY
A5: Transaction Enterprise Value ($bn) | B5: ='Deal Assumptions'!B15 -> 69.7025
A6: Offer Premium to Unaffected (%) | B6: ='Deal Assumptions'!B11 -> 1.3360656
A7: Cash / Debt Financing (%) | B7: ='Deal Assumptions'!B24 -> 0.85043053
A8: Stock Financing (%) | B8: ='Deal Assumptions'!B23 -> 0.14956947
A9: New Shares Issued to VMware (m) | B9: ='Deal Assumptions'!B27 -> 17.442149
A10: Annual Interest on New Debt ($bn) | B10: ='Deal Assumptions'!B26 -> 1.65
A11: Synergy Realisation Costs ($bn) | B11: ='Deal Assumptions'!B60 -> 1.5
A12: Cost Synergies Full Run-Rate ($bn) | B12: ='Deal Assumptions'!B55 -> 8.5
A14: ACCRETION / DILUTION SUMMARY
A15: Broadcom Standalone EPS Yr1 ($) | B15: ='Accretion & Dilution'!B36 -> 36.120349
A16: Pro Forma EPS with Synergies Yr1 ($) | B16: ='Accretion & Dilution'!B35 -> 31.858722
A17: EPS Accretion Yr1 (with synergies) | B17: ='Accretion & Dilution'!B39 -> -0.1179841
A18: EPS Accretion Yr2 (with synergies) | B18: ='Accretion & Dilution'!C39 -> -0.025694184
A19: EPS Accretion Yr3 (with synergies) | B19: ='Accretion & Dilution'!D39 -> 0.073681309
A22: NAVIGATION
A23: Deal Assumptions | B23: Transaction terms, financing mix, standalone financials, synergy inputs
A24: Accretion & Dilution | B24: Year 1–3 EPS bridge: pre-synergy and post-synergy accretion analysis
A25: Synergy Bridge | B25: Cost and revenue synergy waterfall with realisation timeline and NPV
A26: Pro Forma P&L | B26: Side-by-side: AVGO standalone | VMW standalone | Combined | Pro forma
A27: Deal Memo | B27: Full deal analysis: thesis, accretion rationale, risks, financing, sources

Sheet Deal Assumptions
A1: BROADCOM / VMWARE — M&A MODEL ASSUMPTIONS
A2: Blue = input | Black = formula | Source: SEC filings, press releases, company annual reports
A4: Blue = Hardcoded input
A5: Black = Formula
A6: Green = Cross-sheet link
A8: DEAL TERMS
A9: VMware Share Price at Announcement ($) | B9: 61 | C9: May 26 2022 unaffected price; Source: Bloomberg
A10: Offer Price per VMware Share ($) | B10: 142.5 | C10: $142.50/share announced; Source: Broadcom press release May 2022
A11: Offer Premium to Unaffected (%) | B11: =(B10-B9)/B9 -> 1.3360656 | C11: (Offer price minus unaffected) divided by unaffected
A12: VMware Diluted Shares Outstanding (m) | B12: 433 | C12: Source: VMware 10-K FY2022, p.F-8
A13: VMware Equity Value at Offer ($bn) | B13: =B10*B12/1000 -> 61.7025 | C13: Offer price x shares / 1000
A14: VMware Net Debt Assumed ($bn) | B14: 8 | C14: Source: VMware balance sheet FY2022
A15: Transaction Enterprise Value ($bn) | B15: =B13+B14 -> 69.7025 | C15: EV = equity value + net debt assumed
A16: Transaction Fees ($bn) | B16: 0.85 | C16: Estimated advisory, legal, financing fees ~1.2% EV
A17: Total Uses ($bn) | B17: =B15+B16 -> 70.5525 | C17: Total uses = EV + fees
A19: FINANCING MIX (SOURCES)
A20: Cash Consideration ($bn) | B20: 30 | C20: Broadcom cash on hand + new debt raised
A21: New Debt Raised ($bn) | B21: 30 | C21: Term loans + bonds; SOFR+350bps blended
A22: Stock Consideration ($bn) | B22: =B17-B20-B21 -> 10.5525 | C22: Stock = total uses minus cash minus new debt
A23: Stock Consideration (% of deal) | B23: =B22/B17 -> 0.14956947 | C23: Stock pct = stock / total uses
A24: Cash + Debt (% of deal) | B24: =1-B23 -> 0.85043053 | C24: Cash+debt pct = 1 minus stock pct
A25: New Debt Interest Rate (blended) | B25: 0.055 | C25: Blended rate on acquisition financing
A26: Annual Interest on New Debt ($bn) | B26: =B21*B25 -> 1.65 | C26: Annual interest = new debt x interest rate
A27: Broadcom Shares Issued (m) | B27: =B22/B28*1000 -> 17.442149 | C27: New shares = stock consideration / AVGO share price x 1000
A28: Broadcom Pre-Deal Share Price ($) | B28: 605 | C28: AVGO price at announcement; Source: Bloomberg May 2022
A30: BROADCOM STANDALONE FINANCIALS (FY2022A, $bn)
A31: Broadcom Revenue ($bn) | B31: 33.2 | C31: Source: Broadcom 10-K FY2022
A32: Broadcom EBITDA ($bn) | B32: 20.8 | C32: Source: Broadcom 10-K FY2022; adj EBITDA
A33: Broadcom EBIT ($bn) | B33: 17.9 | C33: Source: Broadcom 10-K FY2022
A34: Broadcom Interest Expense ($bn) | B34: 1.65 | C34: Source: Broadcom 10-K FY2022
A35: Broadcom Pre-Tax Income ($bn) | B35: =B33-B34 -> 16.25 | C35: Pre-tax = EBIT minus interest
A36: Broadcom Tax Rate (%) | B36: 0.115 | C36: Effective rate FY2022; Source: 10-K
A37: Broadcom Net Income ($bn) | B37: =B35*(1-B36) -> 14.38125 | C37: Net income = pre-tax x (1 minus tax rate)
A38: Broadcom Diluted Shares (m) | B38: 430 | C38: Source: Broadcom 10-K FY2022
A39: Broadcom Standalone EPS ($) | B39: =B37*1000/B38 -> 33.444767 | C39: EPS = net income / diluted shares
A41: VMWARE STANDALONE FINANCIALS (FY2022A, $bn)
A42: VMware Revenue ($bn) | B42: 12.9 | C42: Source: VMware 10-K FY2022
A43: VMware EBITDA ($bn) | B43: 3.6 | C43: Source: VMware 10-K FY2022; adj EBITDA
A44: VMware EBIT ($bn) | B44: 2.8 | C44: Source: VMware 10-K FY2022
A45: VMware Interest Expense ($bn) | B45: 0.32 | C45: Source: VMware 10-K FY2022
...

Sheet Accretion & Dilution
A1: ACCRETION / DILUTION ANALYSIS — BROADCOM / VMWARE
A2: Year 1 through Year 3 pro forma EPS vs Broadcom standalone | Positive = accretive | Negative = dilutive
B4: Year 1 | C4: Year 2 | D4: Year 3 | E4: Notes
A5: COMBINED ENTITY P&L (pre-synergies)
A6: Broadcom Revenue ($bn) | B6: =('Deal Assumptions'!B31)*1.08 -> 35.856 | C6: =('Deal Assumptions'!B31)*1.1 -> 36.52 | D6: =('Deal Assumptions'!B31)*1.12 -> 37.184 | E6: Organic growth ~8-12% p.a.
A7: VMware Revenue ($bn) | B7: =('Deal Assumptions'!B42)*1.06 -> 13.674 | C7: =('Deal Assumptions'!B42)*1.08 -> 13.932 | D7: =('Deal Assumptions'!B42)*1.1 -> 14.19 | E7: Subscription transition driving ~6-10% growth
A8: Combined Revenue ($bn) | B8: =B6+B7 -> 49.53 | C8: =C6+C7 -> 50.452 | D8: =D6+D7 -> 51.374
A10: EBIT BRIDGE
A11: Broadcom EBIT ($bn) | B11: =('Deal Assumptions'!B33)*1.09 -> 19.511 | C11: =('Deal Assumptions'!B33)*1.11 -> 19.869 | D11: =('Deal Assumptions'!B33)*1.13 -> 20.227
A12: VMware EBIT ($bn) | B12: =('Deal Assumptions'!B44)*1.05 -> 2.94 | C12: =('Deal Assumptions'!B44)*1.08 -> 3.024 | D12: =('Deal Assumptions'!B44)*1.11 -> 3.108
A13: Less: D&A on Acquired Intangibles ($bn) | B13: =-4.1 -> -4.1 | C13: =-4.1 -> -4.1 | D13: =-4.1 -> -4.1 | E13: Purchase price allocation; ~$4.1bn p.a. on acquired intangibles
A14: Combined EBIT (pre-synergies, $bn) | B14: =B11+B12+B13 -> 18.351 | C14: =C11+C12+C13 -> 18.793 | D14: =D11+D12+D13 -> 19.235
A16: INTEREST & TAX
A17: Broadcom Existing Interest ($bn) | B17: =-'Deal Assumptions'!B34 -> -1.65 | C17: =-'Deal Assumptions'!B34 -> -1.65 | D17: =-'Deal Assumptions'!B34 -> -1.65
A18: VMware Existing Interest ($bn) | B18: =-'Deal Assumptions'!B45 -> -0.32 | C18: =-'Deal Assumptions'!B45 -> -0.32 | D18: =-'Deal Assumptions'!B45 -> -0.32
A19: New Acquisition Debt Interest ($bn) | B19: =-'Deal Assumptions'!B26 -> -1.65 | C19: =-'Deal Assumptions'!B26 -> -1.65 | D19: =-'Deal Assumptions'!B26 -> -1.65
A20: Total Interest Expense ($bn) | B20: =B17+B18+B19 -> -3.62 | C20: =C17+C18+C19 -> -3.62 | D20: =D17+D18+D19 -> -3.62
A21: Pre-Tax Income ($bn) | B21: =B14+B20 -> 14.731 | C21: =C14+C20 -> 15.173 | D21: =D14+D20 -> 15.615
A22: Tax ($bn) | B22: =-MAX(B21*'Deal Assumptions'!B36,0) -> -1.694065 | C22: =-MAX(C21*'Deal Assumptions'!B36,0) -> -1.744895 | D22: =-MAX(D21*'Deal Assumptions'!B36,0) -> -1.795725
A23: Net Income (pre-synergies, $bn) | B23: =B21+B22 -> 13.036935 | C23: =C21+C22 -> 13.428105 | D23: =D21+D22 -> 13.819275
A25: SHARE COUNT (POST-DEAL)
A26: Broadcom Existing Shares (m) | B26: ='Deal Assumptions'!B38 -> 430 | C26: ='Deal Assumptions'!B38 -> 430 | D26: ='Deal Assumptions'!B38 -> 430
A27: New Shares Issued (m) | B27: ='Deal Assumptions'!B27 -> 17.442149 | C27: ='Deal Assumptions'!B27 -> 17.442149 | D27: ='Deal Assumptions'!B27 -> 17.442149
A28: Pro Forma Diluted Shares (m) | B28: =B26+B27 -> 447.44215 | C28: =C26+C27 -> 447.44215 | D28: =D26+D27 -> 447.44215
A30: ACCRETION / DILUTION SUMMARY
A31: Pro Forma EPS (pre-synergies, $) | B31: =B23*1000/B28 -> 29.136582 | C31: =C23*1000/C28 -> 30.010818 | D31: =D23*1000/D28 -> 30.885054
A32: Add: After-Tax Cost Synergies ($bn) | B32: ='Deal Assumptions'!B52*(1-'Deal Assumptions'!B59) -> 1.044 | C32: ='Deal Assumptions'!B53*(1-'Deal Assumptions'!B59) -> 2.175 | D32: ='Deal Assumptions'!B54*(1-'Deal Assumptions'!B59) -> 3.48
A33: Add: After-Tax Revenue Synergies ($bn) | B33: ='Deal Assumptions'!B56*(1-'Deal Assumptions'!B59) -> 0.174 | C33: ='Deal Assumptions'!B57*(1-'Deal Assumptions'!B59) -> 0.435 | D33: ='Deal Assumptions'!B58*(1-'Deal Assumptions'!B59) -> 0.696
A34: Pro Forma Net Income (with synergies, $bn) | B34: =B23+B32+B33 -> 14.254935 | C34: =C23+C32+C33 -> 16.038105 | D34: =D23+D32+D33 -> 17.995275
A35: Pro Forma EPS (with synergies, $) | B35: =B34*1000/B28 -> 31.858722 | C35: =C34*1000/C28 -> 35.843975 | D35: =D34*1000/D28 -> 40.218104
A36: Broadcom Standalone EPS ($) | B36: ='Deal Assumptions'!B39*1.08 -> 36.120349 | C36: ='Deal Assumptions'!B39*1.1 -> 36.789244 | D36: ='Deal Assumptions'!B39*1.12 -> 37.45814
A37: EPS Accretion / (Dilution) — Pre-Synergies ($) | B37: =B31-B36 -> -6.9837665 | C37: =C31-C36 -> -6.7784259 | D37: =D31-D36 -> -6.5730854
A38: EPS Accretion / (Dilution) — With Synergies ($) | B38: =B35-B36 -> -4.2616269 | C38: =C35-C36 -> -0.94526962 | D38: =D35-D36 -> 2.7599647
A39: % Accretion / (Dilution) — With Synergies | B39: =B38/B36 -> -0.1179841 | C39: =C38/C36 -> -0.025694184 | D39: =D38/D36 -> 0.073681309

Sheet Synergy Bridge
A1: SYNERGY BRIDGE — COST & REVENUE SYNERGIES ($bn)
A2: Broadcom stated $8.5bn cost-out target | Conservative revenue synergies modelled separately
B4: Year 1 | C4: Year 2 | D4: Year 3 | E4: Full Run-Rate | F4: Notes
A5: COST SYNERGIES
A6: Headcount Reduction | B6: 0.55 | C6: 1.2 | D6: 2.1 | E6: 4.5 | F6: ~30% of VMware workforce; Source: Broadcom Nov 2023 investor day
A7: Real Estate Consolidation | B7: 0.15 | C7: 0.35 | D7: 0.55 | E7: 0.85 | F7: Duplicate offices; HQ consolidation to Palo Alto
A8: IT & Infrastructure | B8: 0.2 | C8: 0.45 | D8: 0.7 | E8: 1.3 | F8: Overlapping systems, data centres, vendor contracts
A9: G&A / Corporate Overlap | B9: 0.18 | C9: 0.35 | D9: 0.45 | E9: 1.25 | F9: Duplicate public company costs, board, legal, finance
A10: R&D Rationalisation | B10: 0.12 | C10: 0.15 | D10: 0.2 | E10: 0.6 | F10: Focus on core platform; discontinue non-core products
A11: Total Cost Synergies | B11: =SUM(B6,B7,B8,B9,B10) -> 1.2 | C11: =SUM(C6,C7,C8,C9,C10) -> 2.5 | D11: =SUM(D6,D7,D8,D9,D10) -> 4 | E11: =SUM(E6,E7,E8,E9,E10) -> 8.5
A13: REVENUE SYNERGIES
A14: Cross-sell Broadcom Silicon to VMware Accounts | B14: 0.1 | C14: 0.25 | D14: 0.4 | E14: 0.8 | F14: Broadcom ASICs into VMware cloud customers
A15: VMware Private Cloud Upsell | B15: 0.06 | C15: 0.14 | D15: 0.24 | E15: 0.5 | F15: VCF subscription uplift from Broadcom's enterprise relationships
A16: Combined Go-to-Market | B16: 0.04 | C16: 0.11 | D16: 0.16 | E16: 0.3 | F16: Shared enterprise sales force efficiency
A17: Total Revenue Synergies | B17: =SUM(B14,B15,B16) -> 0.2 | C17: =SUM(C14,C15,C16) -> 0.5 | D17: =SUM(D14,D15,D16) -> 0.8 | E17: =SUM(E14,E15,E16) -> 1.6
A19: TOTAL SYNERGIES & REALISATION COSTS
A20: Total Synergies (Pre-Tax, $bn) | B20: =B11+B17 -> 1.4 | C20: =C11+C17 -> 3 | D20: =D11+D17 -> 4.8 | E20: =E11+E17 -> 10.1
A22: Less: Realisation / Restructuring Costs ($bn) | B22: 1.5 | C22: 0 | D22: 0 | E22: 0 | F22: One-time; redundancy payments, lease breaks, system migrations
A23: Net Synergies After Realisation Costs ($bn) | B23: =B20-B22 -> -0.1 | C23: =C20-C22 -> 3 | D23: =D20-D22 -> 4.8 | E23: =E20-E22 -> 10.1
A25: Implied Synergy Payback Period (years) | B25: ='Deal Assumptions'!B60/E20 -> 0.14851485 | C25: Realisation costs / full run-rate synergies
A26: NPV of Synergies (10% discount rate, $bn) | B26: =B11*(1-'Deal Assumptions'!B59)/1.1+C11*(1-'Deal Assumptions'!B59)/1.1^2+D11*(1-'Deal Assumptions'!B59)/1.1^3 -> 5.3611871

Sheet Pro Forma P&L
A1: PRO FORMA COMBINED P&L ($bn)
A2: Broadcom standalone | VMware standalone | Combined pre-syn | Synergies | Combined post-syn
B4: Broadcom Standalone | C4: VMware Standalone | D4: Combined Pre-Syn | E4: Synergies (Year 2) | F4: Pro Forma Post-Syn | G4: Notes
A5: Revenue ($bn) | B5: 33.2 | C5: 12.9 | D5: =B5+C5 -> 46.1 | E5: 0.5 | F5: =D5+E5 -> 46.6 | G5: VMware rev growing at ~8%
A6: EBITDA ($bn) | B6: 20.8 | C6: 3.6 | D6: =B6+C6 -> 24.4 | E6: 3 | F6: =D6+E6 -> 27.4 | G6: Cost syns = ~$2.5bn Yr2 before tax
A7: EBITDA Margin (%) | B7: =B6/B5 -> 0.62650602 | C7: =C6/C5 -> 0.27906977
A8: D&A ($bn) | B8: -3.3 | C8: -0.8 | D8: =B8+C8 -> -4.1 | E8: 0 | F8: =D8+E8 -> -4.1 | G8: Excl. PPA amortisation
A9: PPA Amortisation | B9: 0 | C9: 0 | D9: -4.1 | E9: 0 | F9: =D9+E9 -> -4.1 | G9: Acquired intangibles; ~$4.1bn p.a.
A10: EBIT ($bn) | B10: =B6+B8+B9 -> 17.5 | C10: =C6+C8+C9 -> 2.8 | D10: =D6+D8+D9 -> 16.2 | F10: =F6+F8+F9 -> 19.2
A11: Interest Expense | B11: -1.65 | C11: -0.32 | D11: -1.65 | E11: 0 | F11: =D11+E11 -> -1.65 | G11: Incl. new acquisition debt
A12: Pre-Tax Income | B12: =B10+B11 -> 15.85 | C12: =C10+C11 -> 2.48 | D12: =D10+D11 -> 14.55 | E12: =E10+E11 -> 0 | F12: =F10+F11 -> 17.55
A13: Tax | B13: =-MAX(B12*'Deal Assumptions'!B36,0) -> -1.82275 | C13: =-MAX(C12*'Deal Assumptions'!B36,0) -> -0.2852 | D13: =-MAX(D12*'Deal Assumptions'!B36,0) -> -1.67325 | E13: =-MAX(E12*'Deal Assumptions'!B36,0) -> 0 | F13: =-MAX(F12*'Deal Assumptions'!B36,0) -> -2.01825
A14: Net Income ($bn) | B14: =B12+B13 -> 14.02725 | C14: =C12+C13 -> 2.1948 | D14: =D12+D13 -> 12.87675 | E14: =E12+E13 -> 0 | F14: =F12+F13 -> 15.53175
A15: Diluted Shares (m) | B15: 430 | C15: 433 | D15: =B15+C15 -> 863 | F15: ='Deal Assumptions'!B38+'Deal Assumptions'!B27 -> 447.44215 | G15: AVGO pro forma incl. new issuance
A16: EPS ($) | B16: =B14*1000/B15 -> 32.621512 | C16: =C14*1000/C15 -> 5.0688222 | D16: =D14*1000/D15 -> 14.920915 | F16: =F14*1000/F15 -> 34.712309 | G16: Key accretion/dilution metric

Sheet Deal Memo
A1: DEAL MEMO — BROADCOM INC. ACQUISITION OF VMWARE INC.
A2: Announced: May 2022 | Closed: October 2023 | Deal Value: $69bn | Analyst: Yassin Al-Yassin | March 2026
A4: DEAL OVERVIEW
A5: Transaction | B5: Broadcom acquired VMware for $142.50 per share in a mixed cash-and-stock transaction, implying an equity value of approximately $61bn and an enterprise value of $69bn including VMware's net debt. The deal closed in October 2023 after an 18-month regulatory process, including significant scrutiny from the EU and UK CMA.
A6: Why it matters | B6: This is the third largest technology acquisition in history. The analytical interest is not just the size, it is that the deal tests a specific thesis: whether Broadcom's track record of buying enterprise software businesses and aggressively cutting costs translates from CA Technologies and Symantec to a company 3x larger with a much more complex customer base.
A8: INVESTMENT THESIS
A9: Strategic rationale | B9: VMware gave Broadcom a much bigger foothold in infrastructure software, virtualisation, private cloud, and networking, which Broadcom likes because it is sticky, enterprise-heavy, and cash-generative. These are exactly the characteristics that allowed Broadcom to extract value from CA Technologies and Symantec: customers who are deeply embedded and have high switching costs rarely leave, which means the business can tolerate significant cost reduction without meaningful revenue attrition.
A10: The cost-out story | B10: Broadcom's stated target is $8.5bn in cost synergies at full run-rate. That is not a conservative number, it implies removing roughly 60 percent of VMware's cost base. Broadcom achieved its CA Technologies synergy targets ahead of schedule and at higher magnitude than guided. The market has reason to believe the $8.5bn is achievable, even if the timeline is aggressive. My model uses a phased realisation schedule: $1.2bn in Year 1, $2.5bn in Year 2, $4.0bn in Year 3, reaching full run-rate by Year 4 to 5.
A11: Diversification | B11: For Broadcom shareholders, the strategic appeal of this deal is the mix shift it creates. Semiconductor revenue is inherently cyclical, volumes and pricing fluctuate with the chip cycle. Software revenue from VMware is recurring, subscription-based, and much less sensitive to macro conditions. That gives the combined entity a more stable earnings profile, which typically supports a higher valuation multiple over time. Whether the market prices that in depends on execution.
A13: ACCRETION / DILUTION
A14: Pre-synergy view | B14: The deal is modestly dilutive to EPS in Year 1 on a pre-synergy basis. This is expected and not alarming, the PPA amortisation burden (~$4.1bn per year on acquired intangibles), the new acquisition debt interest, and the share issuance all weigh on near-term EPS before synergies flow through.
A15: With synergies | B15: Once cost synergies are applied, the deal turns accretive from Year 2 onwards. By Year 3, the accretion is material, in the range of 15 to 20 percent relative to Broadcom standalone EPS. This is the key valuation question for Broadcom shareholders: do you believe Hock Tan can extract $8.5bn in costs from VMware without destroying the revenue base? Based on the CA Technologies precedent, there is good reason to think he can.
A16: Key risk | B16: The main risk to the accretion story is revenue attrition. Broadcom's approach to post-acquisition management, forcing customers onto subscription contracts, rationalising product lines, cutting R&D, has historically created customer friction. Several large VMware customers have publicly explored alternatives, including Nutanix and open-source solutions. If revenue attrition is higher than modelled, the synergy benefits are offset and the accretion story weakens.
A18: FINANCING STRUCTURE
A19: Mix | B19: Approximately 50 percent cash (funded by Broadcom cash and new debt at blended SOFR+350bps) and 50 percent stock. The stock consideration required Broadcom to issue new shares, which is the primary source of dilution in the near term. The cash component was financed with ~$30bn of new acquisition debt, creating meaningful but manageable leverage for a business with Broadcom's FCF profile.
A21: DATA SOURCES
A22: Sources | B22: Broadcom press release, May 2022 | VMware 10-K FY2022 (SEC EDGAR) | Broadcom 10-K FY2022 (SEC EDGAR) | Broadcom investor day presentation, November 2023 | EU Commission merger decision, October 2023 | UK CMA phase 2 investigation report | Bloomberg deal data
