Workbook

Sheet Assumptions
A1: eVTOL OPERATOR — UNIT ECONOMICS MODEL | ASSUMPTIONS
A2: Blue = hardcoded input | Black = formula | All monetary values in £ unless stated | Analyst: Yassin Al-Yassin | March 2026
A4: Blue = Hardcoded input
A5: Black = Formula
A6: Green = Cross-sheet link
A8: AIRCRAFT ASSUMPTIONS
A9: Aircraft Type | B9: Joby S4 | C9: Leading eVTOL; 4-pax, 200km range
A10: Seats per Aircraft | B10: 4 | C10: Passenger seats (excl. pilot)
A11: Aircraft Purchase Price (£m) | B11: 2.2 | C11: Est. OEM list price at scale
A12: Useful Life (years) | B12: 15 | C12: Conservative; subject to cert. history
A13: Residual Value % of Cost | B13: 0.1 | C13: 10% salvage
A14: Annual Depreciation (£) | B14: =(B11*1000000*(1-B13))/B12 -> 132000 | C14: (Cost - Residual) / Life
A15: Max Flight Hours per Day | B15: 12 | C15: Operations window (6am–10pm)
A16: Turnaround Time (mins) | B16: 10 | C16: Battery swap + boarding
A17: Average Flight Duration (mins) | B17: 22 | C17: Typical urban route: ~30km
A18: Flights per Day (theoretical) | B18: =(B15*60)/(B17+B16) -> 22.5 | C18: 12hr x 60 / (flight + turnaround)
A19: Target Utilisation Rate | B19: 0.7 | C19: % of theoretical max; 70% = realistic yr3+
A20: Effective Flights per Day | B20: =B18*B19 -> 15.75 | C20: theoretical x utilisation
A21: Operating Days per Year | B21: 330 | C21: Accounting for maintenance downtime
A22: Annual Flights per Aircraft | B22: =B20*B21 -> 5197.5 | C22: effective/day x days/year
A24: REVENUE ASSUMPTIONS
A25: Average Fare per Seat (£) | B25: 85 | C25: Blended: premium urban route pricing
A26: Load Factor | B26: 0.78 | C26: % seats filled per flight; 78% realistic at scale
A27: Revenue per Flight (£) | B27: =B25*B10*B26 -> 265.2 | C27: fare x seats x load factor
A28: Ancillary Revenue % of Ticket | B28: 0.05 | C28: Baggage, booking fees
A29: Total Revenue per Flight (£) | B29: =B27*(1+B28) -> 278.46 | C29: ticket + ancillary
A31: OPERATING COST ASSUMPTIONS (per flight)
A32: Energy Cost per Flight (£) | B32: 8 | C32: Battery charge ~35kWh; £0.22/kWh commercial rate
A33: Pilot Cost per Flight (£) | B33: 28 | C33: Blended pilot salary + benefits / annual flights
A34: Maintenance Cost per Flight (£) | B34: 14 | C34: Scheduled + unscheduled; ~£0.07/flight hr equiv
A35: Landing & Vertiport Fees (£) | B35: 12 | C35: Vertiport slot + handling; est. CAA framework
A36: Insurance per Flight (£) | B36: 6 | C36: Aviation hull + liability; nascent market premium
A37: Navigation / ATC fees (£) | B37: 4 | C37: UTM / U-space service charges
A38: Other Variable Costs (£) | B38: 5 | C38: Cleaning, comms, sundry
A39: Total Variable Cost per Flight (£) | B39: =B32+B33+B34+B35+B36+B37+B38 -> 77 | C39: Sum of above
A41: ANNUAL FIXED COSTS (per aircraft)
A42: Annual Depreciation (£) | B42: =B14 -> 132000 | C42: Linked from aircraft assumptions above
A43: Base Salary Overhead (£/yr) | B43: 45000 | C43: Operations, dispatch, safety mgmt staff
A44: Software & Fleet Mgmt (£/yr) | B44: 8000 | C44: UTM integration, ops software
A45: Regulatory & Certification (£/yr) | B45: 12000 | C45: CAA ongoing cert., safety audits
...

Sheet Unit Economics
A1: eVTOL OPERATOR — UNIT ECONOMICS (PER AIRCRAFT, PER YEAR)
A2: All values per single aircraft | Green = cross-sheet link | Based on Assumptions tab
A4: REVENUE
A5: Annual Flights per Aircraft | B5: =Assumptions!B22 -> 5197.5
A6: Total Revenue per Flight (£) | B6: =Assumptions!B29 -> 278.46
A7: Annual Revenue per Aircraft (£) | B7: =B5*B6 -> 1447295.8
A9: VARIABLE COSTS
A10: Variable Cost per Flight (£) | B10: =Assumptions!B39 -> 77
A11: Total Variable Cost per Year (£) | B11: =B5*B10 -> 400207.5
A12: Variable Cost % Revenue | B12: =B11/B7 -> 0.27652086
A14: CONTRIBUTION & FIXED COSTS
A15: Contribution per Flight (£) | B15: =B6-B10 -> 201.46
A16: Contribution Margin % | B16: =B15/B6 -> 0.72347914
A17: Total Annual Fixed Costs (£) | B17: =Assumptions!B47 -> 212000
A18: EBITDA per Aircraft (£) | B18: =B7-B11-B17 -> 835088.35
A19: EBITDA Margin % | B19: =B18/B7 -> 0.57699906
A20: Depreciation (£) | B20: =Assumptions!B14 -> 132000
A21: EBIT per Aircraft (£) | B21: =B18-B20 -> 703088.35
A22: EBIT Margin % | B22: =B21/B7 -> 0.48579449
A25: BREAKEVEN ANALYSIS
A26: Breakeven Flights per Year | B26: =B17/B15 -> 1052.3181 | C26: Fixed costs / contribution per flight
A27: Breakeven as % of Annual Capacity | B27: =B26/B5 -> 0.2024662 | C27: Breakeven flights / annual flights
A28: Breakeven Utilisation Rate | B28: =B26/(Assumptions!B18*Assumptions!B21) -> 0.14172634 | C28: At what utilisation does the aircraft break even
A29: Margin of Safety | B29: =(B5-B26)/B5 -> 0.7975338 | C29: (Actual − Breakeven) / Actual flights

Sheet 5-Year P&L
A1: eVTOL OPERATOR — 5-YEAR P&L PROJECTION (£)
A2: Fleet ramp-up model | Per-aircraft economics × fleet size | All values in £
B4: Year 1 | C4: Year 2 | D4: Year 3 | E4: Year 4 | F4: Year 5
A5: FLEET
A6: Aircraft in Fleet | B6: =Assumptions!B50 -> 2 | C6: =Assumptions!B51 -> 5 | D6: =Assumptions!B52 -> 12 | E6: =Assumptions!B53 -> 25 | F6: =Assumptions!B54 -> 40
A7: Utilisation Rate | B7: =Assumptions!B55 -> 0.45 | C7: =Assumptions!B56 -> 0.58 | D7: =Assumptions!B57 -> 0.7 | E7: =Assumptions!B58 -> 0.75 | F7: =Assumptions!B59 -> 0.78
A8: Flights per Aircraft per Year | B8: =Assumptions!B18*B7*Assumptions!B21 -> 3341.25 | C8: =Assumptions!B18*C7*Assumptions!B21 -> 4306.5 | D8: =Assumptions!B18*D7*Assumptions!B21 -> 5197.5 | E8: =Assumptions!B18*E7*Assumptions!B21 -> 5568.75 | F8: =Assumptions!B18*F7*Assumptions!B21 -> 5791.5
A9: Total Fleet Flights per Year | B9: =B6*B8 -> 6682.5 | C9: =C6*C8 -> 21532.5 | D9: =D6*D8 -> 62370 | E9: =E6*E8 -> 139218.75 | F9: =F6*F8 -> 231660
A11: REVENUE (£)
A12: Revenue per Flight (£) | B12: =Assumptions!B29 -> 278.46 | C12: =Assumptions!B29 -> 278.46 | D12: =Assumptions!B29 -> 278.46 | E12: =Assumptions!B29 -> 278.46 | F12: =Assumptions!B29 -> 278.46
A13: Total Revenue (£) | B13: =B9*B12 -> 1860808.9 | C13: =C9*C12 -> 5995939.9 | D13: =D9*D12 -> 17367550 | E13: =E9*E12 -> 38766853 | F13: =F9*F12 -> 64508044
A14: YoY Revenue Growth | B14: — | C14: =(C13-B13)/B13 -> 2.2222222 | D14: =(D13-C13)/C13 -> 1.8965517 | E14: =(E13-D13)/D13 -> 1.2321429 | F14: =(F13-E13)/E13 -> 0.664
A16: COSTS (£)
A17: Variable Costs (£) | B17: =B9*Assumptions!B39 -> 514552.5 | C17: =C9*Assumptions!B39 -> 1658002.5 | D17: =D9*Assumptions!B39 -> 4802490 | E17: =E9*Assumptions!B39 -> 10719844 | F17: =F9*Assumptions!B39 -> 17837820
A18: Fixed Costs (£) | B18: =B6*Assumptions!B47 -> 424000 | C18: =C6*Assumptions!B47 -> 1060000 | D18: =D6*Assumptions!B47 -> 2544000 | E18: =E6*Assumptions!B47 -> 5300000 | F18: =F6*Assumptions!B47 -> 8480000
A19: Total Costs (£) | B19: =B17+B18 -> 938552.5 | C19: =C17+C18 -> 2718002.5 | D19: =D17+D18 -> 7346490 | E19: =E17+E18 -> 16019844 | F19: =F17+F18 -> 26317820
A21: PROFITABILITY (£)
A22: EBITDA (£) | B22: =B13-B17-(B18-B6*Assumptions!B14) -> 1186256.4 | C22: =C13-C17-(C18-C6*Assumptions!B14) -> 3937937.4 | D22: =D13-D17-(D18-D6*Assumptions!B14) -> 11605060 | E22: =E13-E17-(E18-E6*Assumptions!B14) -> 26047009 | F22: =F13-F17-(F18-F6*Assumptions!B14) -> 43470224
A23: EBITDA Margin | B23: =B22/B13 -> 0.63749503 | C23: =C22/C13 -> 0.65676733 | D23: =D22/D13 -> 0.66820364 | E23: =E22/E13 -> 0.67188867 | F23: =F22/F13 -> 0.67387292
A24: Depreciation (£) | B24: =B6*Assumptions!B14 -> 264000 | C24: =C6*Assumptions!B14 -> 660000 | D24: =D6*Assumptions!B14 -> 1584000 | E24: =E6*Assumptions!B14 -> 3300000 | F24: =F6*Assumptions!B14 -> 5280000
A25: EBIT (£) | B25: =B22-B24 -> 922256.45 | C25: =C22-C24 -> 3277937.4 | D25: =D22-D24 -> 10021060 | E25: =E22-E24 -> 22747009 | F25: =F22-F24 -> 38190224
A26: EBIT Margin | B26: =IFERROR(B25/B13,0) -> 0.49562125 | C26: =IFERROR(C25/C13,0) -> 0.54669284 | D26: =IFERROR(D25/D13,0) -> 0.57699906 | E26: =IFERROR(E25/E13,0) -> 0.5867644 | F26: =IFERROR(F25/F13,0) -> 0.59202266
A28: CAPEX & CASH
A29: Aircraft Additions | B29: =Assumptions!B50 -> 2 | C29: =Assumptions!B51-B6 -> 3 | D29: =Assumptions!B52-C6 -> 7 | E29: =Assumptions!B53-D6 -> 13 | F29: =Assumptions!B54-E6 -> 15
A30: Capex — Aircraft (£) | B30: =B29*Assumptions!B11*1000000 -> 4400000 | C30: =C29*Assumptions!B11*1000000 -> 6600000 | D30: =D29*Assumptions!B11*1000000 -> 15400000 | E30: =E29*Assumptions!B11*1000000 -> 28600000 | F30: =F29*Assumptions!B11*1000000 -> 33000000
A31: Operating Cash Flow (EBITDA − Capex) (£) | B31: =B22-B30 -> -3213743.5 | C31: =C22-C30 -> -2662062.6 | D31: =D22-D30 -> -3794939.8 | E31: =E22-E30 -> -2552990.6 | F31: =F22-F30 -> 10470224
A32: Cumulative Cash Position (£) | B32: =B31 -> -3213743.5 | C32: =B32+C31 -> -5875806.1 | D32: =C32+D31 -> -9670745.9 | E32: =D32+E31 -> -12223737 | F32: =E32+F31 -> -1753512.9

Sheet Sensitivity
A1: SENSITIVITY — EBIT PER AIRCRAFT (£) vs FARE & UTILISATION
A2: Green = profitable | Red = loss-making | Amber = base case (£85 fare, 70% utilisation)
A4: Util \ Fare (£) | B4: £60 | C4: £70 | D4: £80 | E4: £85 | F4: £90 | G4: £100 | H4: £110
A5: 45% | B5: 187480 | C5: 296939 | D5: 406399 | E5: 461128 | F5: 515858 | G5: 625317 | H5: 734777
A6: 55% | B6: 276253 | C6: 410037 | D6: 543820 | E6: 610712 | F6: 677604 | G6: 811388 | H6: 945171
A7: 65% | B7: 365026 | C7: 523134 | D7: 681242 | E7: 760296 | F7: 839350 | G7: 997458 | H7: 1155566
A8: 70% | B8: 409413 | C8: 579683 | D8: 749953 | E8: 835088 | F8: 920223 | G8: 1090493 | H8: 1260764
A9: 75% | B9: 453800 | C9: 636232 | D9: 818664 | E9: 909880 | F9: 1001097 | G9: 1183529 | H9: 1365961
A10: 80% | B10: 498186 | C10: 692781 | D10: 887375 | E10: 984672 | F10: 1081970 | G10: 1276564 | H10: 1471158
A11: 85% | B11: 542573 | C11: 749330 | D11: 956086 | E11: 1059464 | F11: 1162843 | G11: 1369599 | H11: 1576356
A13: Note: Amber = base case | Green = profitable EBIT | Red = loss-making | Per-aircraft, per-year basis
