Workbook

Sheet Dashboard
A1: JET2 PLC — DCF MODEL DASHBOARD
A2: Summary of key outputs | All values linked from model tabs | Analyst: Yassin Al-Yassin | Jan 2026
A4: VALUATION SUMMARY
A5: Enterprise Value (£m) | B5: ='DCF Valuation'!B21 -> 32216.709
A6: Equity Value (£m) | B6: ='DCF Valuation'!B24 -> 32840.309
A7: Implied Share Price (£) | B7: ='DCF Valuation'!B26 -> 161.61569
A8: Current Share Price (£) | B8: =Assumptions!B58 -> 12.6
A9: Implied Upside/(Downside) | B9: ='DCF Valuation'!B28 -> 11.826642
A10: TV as % of EV | B10: ='DCF Valuation'!B16/'DCF Valuation'!B21 -> 0.76673881
A11: WACC | B11: =WACC!B21 -> 0.08448
A12: Terminal Growth Rate | B12: =Assumptions!B54 -> 0.025
A14: KEY FINANCIALS (£m)
A15: Metric | B15: FY2023A | C15: FY2024A | D15: FY2025A | E15: FY2026E
A16: Revenue | B16: 5033.5 | C16: 6255.3 | D16: 7173.5 | E16: ='Income Statement'!E8 -> 7819.5619
A17: EBIT | B17: 394 | C17: 428.2 | D17: 446.5 | E17: ='Income Statement'!E21 -> 2314.5903
A18: EBIT Margin | B18: 0.0783 | C18: 0.0685 | D18: 0.0623 | E18: ='Income Statement'!E21/'Income Statement'!E8 -> 0.296
A19: EBITDA | B19: 579.2 | C19: 677 | D19: 728.6 | E19: ='Income Statement'!E18 -> 2619.5532
A20: Net Income | B20: 290.8 | C20: 399.2 | D20: 446.8 | E20: ='Income Statement'!E27 -> 1754.6927
A21: FCFF | B21: — | C21: — | D21: — | E21: ='Cash Flow'!E17 -> 1641.9509
A23: SCENARIO PRICES (£)
B24: Base Case | C24: Bull Case | D24: Bear Case
A25: Implied Share Price (£) | B25: 22.18 | C25: 47.26 | D25: 5.68
A26: vs Current Price (£12.60) | B26: +76.0% | C26: +275.1% | D26: -54.9%
A28: MODEL CHECKS (SUMMARY)
A29: All checks passing | B29: → See Model Checks tab for detail
A31: NAVIGATION
A32: Assumptions | B32: → All model inputs
A33: WACC | B33: → CAPM build
A34: Income Statement | B34: → P&L projection
A35: Cash Flow | B35: → FCFF build
A36: DCF Valuation | B36: → EV & equity bridge
A37: Sensitivity | B37: → WACC × TGR matrix
A38: Scenarios | B38: → Base / Bull / Bear
A39: Comparables | B39: → Peer multiples
A40: Model Checks | B40: → Integrity checks
A41: Investment Memo | B41: → One-page memo

Sheet Assumptions
A1: JET2 PLC — MODEL ASSUMPTIONS
A2: All blue cells = inputs | Black = formula | Green = cross-sheet link | Source: Jet2 Annual Reports FY2023–FY2025
A4: Blue = Hardcoded input
A5: Black = Formula
A6: Green = Cross-sheet link
A8: WACC ASSUMPTIONS
A9: Risk-Free Rate (10yr UK Gilt) | B9: 0.043 | C9: UK 10yr Gilt ~4.3% (March 2026)
A10: Equity Risk Premium (ERP) | B10: 0.055 | C10: Damodaran UK ERP estimate
A11: Beta (Levered, 2yr weekly) | B11: 1.25 | C11: Jet2 vs FTSE All-Share; aviation sector
A12: Cost of Equity (Ke) | B12: → WACC tab | C12: CAPM: Rf + β×ERP — see WACC tab
A13: Pre-Tax Cost of Debt (Kd) | B13: 0.048 | C13: Blended rate from FY25 notes payable
A14: Tax Rate | B14: 0.25 | C14: UK corporation tax 25%
A15: After-Tax Cost of Debt | B15: → WACC tab | C15: Kd×(1−t)
A16: Equity Weight (E/V) | B16: 0.64 | C16: Mkt cap ~£2.6bn / EV ~£4.1bn
A17: Debt Weight (D/V) | B17: 0.36 | C17: 1 − equity weight
A18: WACC | B18: → WACC tab | C18: Ke×We + Kd×Wd — see WACC tab
A20: REVENUE DRIVERS
B21: Value | C21: Note
A22: Seats Flown FY2025A (m) | B22: 22.3 | C22: Jet2 FY25 pax capacity
A23: Seat Growth FY2026E | B23: 0.09 | C23: Mgmt guided +13% capacity
A24: Seat Growth FY2027E | B24: 0.07
A25: Seat Growth FY2028E | B25: 0.055
A26: Seat Growth FY2029E | B26: 0.045
A27: Seat Growth FY2030E | B27: 0.04
A28: Avg Revenue per Seat FY2025A (£) | B28: 321.7 | C28: £7,174m / 22.3m seats
A29: Rev/Seat Growth FY2026E | B29: 0 | C29: Volume-driven; pricing flat
A30: Rev/Seat Growth FY2027–30E | B30: 0.01 | C30: Modest pricing uplift
A32: MARGIN & COST ASSUMPTIONS
A33: Fuel Cost % Revenue FY2026E | B33: 0.195 | C33: Aviation fuel ~19-20% of revenues
A34: Fuel Cost % Revenue FY2027–30 | B34: 0.185 | C34: Efficiency gains from A321neo
A35: Staff Cost % Revenue | B35: 0.155 | C35: FY25 actual ~15.5%
A36: Aircraft Leases % Revenue | B36: 0.045 | C36: IFRS 16 lease payments
A37: Airport & Handling % Revenue | B37: 0.11 | C37: Slot fees, ground handling
A38: Other Opex % Revenue | B38: 0.16 | C38: Maintenance, IT, overheads
A39: EBITDA Margin FY2026E | B39: Calculated | C39: Calculated: 1 − sum of above costs − D&A
A40: EBIT Margin FY2026E | B40: 0.066 | C40: Slight expansion on operational leverage
A41: EBIT Margin FY2027E | B41: 0.068
A42: EBIT Margin FY2028E | B42: 0.07
A43: EBIT Margin FY2029E | B43: 0.071
A44: EBIT Margin FY2030E | B44: 0.072 | C44: Steady-state; A321neo fully embedded
...

Sheet WACC
A1: WACC CALCULATION — JET2 PLC
A2: All inputs linked from Assumptions tab | CAPM cost of equity | Market value weights
A4: COST OF EQUITY (CAPM)
A5: Risk-Free Rate (Rf) | B5: =Assumptions!B9 -> 0.043
A6: Equity Risk Premium (ERP) | B6: =Assumptions!B10 -> 0.055
A7: Beta (β) | B7: =Assumptions!B11 -> 1.25
A8: Cost of Equity Ke = Rf + β×ERP | B8: =B5+B7*B6 -> 0.11175
A10: COST OF DEBT
A11: Pre-Tax Cost of Debt | B11: =Assumptions!B13 -> 0.048
A12: Tax Rate | B12: =Assumptions!B14 -> 0.25
A13: After-Tax Cost of Debt Kd×(1-t) | B13: =B11*(1-B12) -> 0.036
A15: CAPITAL STRUCTURE
A16: Equity Weight (E/V) | B16: =Assumptions!B16 -> 0.64
A17: Debt Weight (D/V) | B17: =Assumptions!B17 -> 0.36
A18: Check (should = 1.0x) | B18: =B16+B17 -> 1 | C18: ✓ Must equal 1.00x
A20: WACC
A21: WACC = Ke×We + Kd×Wd | B21: =B8*B16+B13*B17 -> 0.08448 | C21: ← Used in DCF discounting and terminal value
A23: WACC SENSITIVITY (varying Beta & ERP)
A24: Beta \ ERP | B24: 0.045 | C24: 0.05 | D24: 0.055 | E24: 0.06 | F24: 0.065
A25: 1 | B25: 0.06928 | C25: 0.07248 | D25: 0.07568 | E25: 0.07888 | F25: 0.08208
A26: 1.1 | B26: 0.07216 | C26: 0.07568 | D26: 0.0792 | E26: 0.08272 | F26: 0.08624
A27: 1.25 | B27: 0.07648 | C27: 0.08048 | D27: 0.08448 | E27: 0.08848 | F27: 0.09248
A28: 1.4 | B28: 0.0808 | C28: 0.08528 | D28: 0.08976 | E28: 0.09424 | F28: 0.09872
A29: 1.5 | B29: 0.08368 | C29: 0.08848 | D29: 0.09328 | E29: 0.09808 | F29: 0.10288

Sheet Income Statement
A1: JET2 PLC — INCOME STATEMENT (£m)
A2: Gray = Historical (actual) | Blue = Forecast | Source: Jet2 Annual Reports
B4: FY2023A | C4: FY2024A | D4: FY2025A | E4: FY2026E | F4: FY2027E | G4: FY2028E | H4: FY2029E | I4: FY2030E
A5: REVENUE DRIVERS
A6: Seats Flown (m) | B6: 17.4 | C6: 20.7 | D6: 22.3 | E6: =D6*(1+Assumptions!B23) -> 24.307 | F6: =E6*(1+Assumptions!B24) -> 26.00849 | G6: =F6*(1+Assumptions!B25) -> 27.438957 | H6: =G6*(1+Assumptions!B26) -> 28.67371 | I6: =H6*(1+Assumptions!B27) -> 29.820658
A7: Avg Revenue per Seat (£) | B7: 289.3 | C7: 302.2 | D7: 321.7 | E7: =D7*(1+Assumptions!B29) -> 321.7 | F7: =E7*(1+Assumptions!B30) -> 324.917 | G7: =F7*(1+Assumptions!B30) -> 328.16617 | H7: =G7*(1+Assumptions!B30) -> 331.44783 | I7: =H7*(1+Assumptions!B30) -> 334.76231
A8: Revenue | B8: 5033.5 | C8: 6255.3 | D8: 7173.5 | E8: =E6*E7 -> 7819.5619 | F8: =F6*F7 -> 8450.6005 | G8: =G6*G7 -> 9004.5374 | H8: =H6*H7 -> 9503.839 | I8: =I6*I7 -> 9982.8325
A9: YoY Growth | B9: — | C9: =(C8-B8)/B8 -> 0.24273368 | D9: =(D8-C8)/C8 -> 0.14678752 | E9: =(E8-D8)/D8 -> 0.090062299 | F9: =(F8-E8)/E8 -> 0.0807 | G9: =(G8-F8)/F8 -> 0.06555 | H9: =(H8-G8)/G8 -> 0.05545 | I9: =(I8-H8)/H8 -> 0.0504
A11: OPERATING COSTS (£m)
A12: Fuel Costs | B12: 982 | C12: 1219 | D12: 1399 | E12: =E8*Assumptions!B33 -> 1524.8146 | F12: =F8*Assumptions!B34 -> 1563.3611 | G12: =G8*Assumptions!B34 -> 1665.8394 | H12: =H8*Assumptions!B34 -> 1758.2102 | I12: =I8*Assumptions!B34 -> 1846.824
A13: Staff Costs | B13: 780.2 | C13: 969.6 | D13: 1111.9 | E13: =E8*Assumptions!B35 -> 1212.0321 | F13: =F8*Assumptions!B35 -> 1309.8431 | G13: =G8*Assumptions!B35 -> 1395.7033 | H13: =H8*Assumptions!B35 -> 1473.095 | I13: =I8*Assumptions!B35 -> 1547.339
A14: Aircraft Leases | B14: 221.5 | C14: 281.5 | D14: 322.8 | E14: =E8*Assumptions!B36 -> 351.88029 | F14: =F8*Assumptions!B36 -> 380.27702 | G14: =G8*Assumptions!B36 -> 405.20418 | H14: =H8*Assumptions!B36 -> 427.67276 | I14: =I8*Assumptions!B36 -> 449.22746
A15: Airport & Handling | B15: 553.7 | C15: 688.1 | D15: 789.1 | E15: =E8*Assumptions!B37 -> 860.15181 | F15: =F8*Assumptions!B37 -> 929.56606 | G15: =G8*Assumptions!B37 -> 990.49912 | H15: =H8*Assumptions!B37 -> 1045.4223 | I15: =I8*Assumptions!B37 -> 1098.1116
A16: Other Operating | B16: 805.4 | C16: 829.7 | D16: 1103.5 | E16: =E8*Assumptions!B38 -> 1251.1299 | F16: =F8*Assumptions!B38 -> 1352.0961 | G16: =G8*Assumptions!B38 -> 1440.726 | H16: =H8*Assumptions!B38 -> 1520.6142 | I16: =I8*Assumptions!B38 -> 1597.2532
A17: Total Operating Costs | B17: =B12+B13+B14+B15+B16 -> 3342.8 | C17: =C12+C13+C14+C15+C16 -> 3987.9 | D17: =D12+D13+D14+D15+D16 -> 4726.3 | E17: =E12+E13+E14+E15+E16 -> 5200.0087 | F17: =F12+F13+F14+F15+F16 -> 5535.1434 | G17: =G12+G13+G14+G15+G16 -> 5897.972 | H17: =H12+H13+H14+H15+H16 -> 6225.0146 | I17: =I12+I13+I14+I15+I16 -> 6538.7553
A18: EBITDA | B18: =B8-B17 -> 1690.7 | C18: =C8-C17 -> 2267.4 | D18: =D8-D17 -> 2447.2 | E18: =E8-E17 -> 2619.5532 | F18: =F8-F17 -> 2915.4572 | G18: =G8-G17 -> 3106.5654 | H18: =H8-H17 -> 3278.8245 | I18: =I8-I17 -> 3444.0772
A19: EBITDA Margin | B19: =B18/B8 -> 0.33588954 | C19: =C18/C8 -> 0.36247662 | D19: =D18/D8 -> 0.34114449 | E19: =E18/E8 -> 0.335 | F19: =F18/F8 -> 0.345 | G19: =G18/G8 -> 0.345 | H19: =H18/H8 -> 0.345 | I19: =I18/I8 -> 0.345
A20: Depreciation & Amortisation | B20: -185.2 | C20: -248.8 | D20: -282.1 | E20: =-E8*Assumptions!B45 -> -304.96291 | F20: =-F8*Assumptions!B45 -> -329.57342 | G20: =-G8*Assumptions!B45 -> -351.17696 | H20: =-H8*Assumptions!B45 -> -370.64972 | I20: =-I8*Assumptions!B45 -> -389.33047
A21: EBIT | B21: =B18+B20 -> 1505.5 | C21: =C18+C20 -> 2018.6 | D21: =D18+D20 -> 2165.1 | E21: =E18+E20 -> 2314.5903 | F21: =F18+F20 -> 2585.8838 | G21: =G18+G20 -> 2755.3884 | H21: =H18+H20 -> 2908.1747 | I21: =I18+I20 -> 3054.7467
A22: EBIT Margin | B22: =B21/B8 -> 0.29909606 | C22: =C21/C8 -> 0.32270235 | D22: =D21/D8 -> 0.3018192 | E22: =E21/E8 -> 0.296 | F22: =F21/F8 -> 0.306 | G22: =G21/G8 -> 0.306 | H22: =H21/H8 -> 0.306 | I22: =I21/I8 -> 0.306
A24: BELOW THE LINE
A25: Net Interest Income / (Expense) | B25: 18.5 | C25: 41.2 | D25: 52.3 | E25: =25 -> 25 | F25: =25 -> 25 | G25: =25 -> 25 | H25: =25 -> 25 | I25: =25 -> 25
A26: Tax | B26: -90.8 | C26: -125.2 | D26: -135.5 | E26: =-(E21+E25)*Assumptions!B14 -> -584.89758 | F26: =-(F21+F25)*Assumptions!B14 -> -652.72094 | G26: =-(G21+G25)*Assumptions!B14 -> -695.09711 | H26: =-(H21+H25)*Assumptions!B14 -> -733.29368 | I26: =-(I21+I25)*Assumptions!B14 -> -769.93669
A27: Net Income | B27: 290.8 | C27: 399.2 | D27: 446.8 | E27: =E21+E25+E26 -> 1754.6927 | F27: =F21+F25+F26 -> 1958.1628 | G27: =G21+G25+G26 -> 2085.2913 | H27: =H21+H25+H26 -> 2199.8811 | I27: =I21+I25+I26 -> 2309.8101

Sheet Cash Flow
A1: JET2 PLC — FREE CASH FLOW BUILD (£m)
A2: FCFF = NOPAT + D&A − Capex − ΔNWC | Gray = Historical | Blue = Forecast
B4: FY2023A | C4: FY2024A | D4: FY2025A | E4: FY2026E | F4: FY2027E | G4: FY2028E | H4: FY2029E | I4: FY2030E
A5: FREE CASH FLOW TO FIRM (FCFF)
A6: EBIT | B6: 394 | C6: 428.2 | D6: 446.5 | E6: ='Income Statement'!E21 -> 2314.5903 | F6: ='Income Statement'!F21 -> 2585.8838 | G6: ='Income Statement'!G21 -> 2755.3884 | H6: ='Income Statement'!H21 -> 2908.1747 | I6: ='Income Statement'!I21 -> 3054.7467
A7: Less: Tax on EBIT | B7: — | C7: -100 | D7: -111.6 | E7: =-E6*Assumptions!B14 -> -578.64758 | F7: =-F6*Assumptions!B14 -> -646.47094 | G7: =-G6*Assumptions!B14 -> -688.84711 | H7: =-H6*Assumptions!B14 -> -727.04368 | I7: =-I6*Assumptions!B14 -> -763.68669
A8: NOPAT | B8: 394 | C8: 328.2 | D8: 334.9 | E8: =E6+E7 -> 1735.9427 | F8: =F6+F7 -> 1939.4128 | G8: =G6+G7 -> 2066.5413 | H8: =H6+H7 -> 2181.1311 | I8: =I6+I7 -> 2291.0601
A9: Add: D&A | B9: 185.2 | C9: 248.8 | D9: 282.1 | E9: =-'Income Statement'!E20 -> 304.96291 | F9: =-'Income Statement'!F20 -> 329.57342 | G9: =-'Income Statement'!G20 -> 351.17696 | H9: =-'Income Statement'!H20 -> 370.64972 | I9: =-'Income Statement'!I20 -> 389.33047
A10: Less: Capex | B10: -193.9 | C10: -403.9 | D10: -391.4 | E10: =-'Income Statement'!E8*Assumptions!B46 -> -437.89547 | F10: =-'Income Statement'!F8*Assumptions!B46 -> -473.23363 | G10: =-'Income Statement'!G8*Assumptions!B46 -> -504.2541 | H10: =-'Income Statement'!H8*Assumptions!B46 -> -532.21498 | I10: =-'Income Statement'!I8*Assumptions!B46 -> -559.03862
A11: Working Capital Detail:
A12: Accounts Receivable (Days × Rev/365) | B12: =Assumptions!B48*'Income Statement'!B8/365 -> 248.2274 | C12: =Assumptions!B48*'Income Statement'!C8/365 -> 308.48055 | D12: =Assumptions!B48*'Income Statement'!D8/365 -> 353.76164 | E12: =Assumptions!B48*'Income Statement'!E8/365 -> 385.62223 | F12: =Assumptions!B48*'Income Statement'!F8/365 -> 416.74194 | G12: =Assumptions!B48*'Income Statement'!G8/365 -> 444.05938 | H12: =Assumptions!B48*'Income Statement'!H8/365 -> 468.68247 | I12: =Assumptions!B48*'Income Statement'!I8/365 -> 492.30407
A13: Inventory (Days × Rev/365) | B13: =Assumptions!B50*'Income Statement'!B8/365 -> 68.952055 | C13: =Assumptions!B50*'Income Statement'!C8/365 -> 85.689041 | D13: =Assumptions!B50*'Income Statement'!D8/365 -> 98.267123 | E13: =Assumptions!B50*'Income Statement'!E8/365 -> 107.11729 | F13: =Assumptions!B50*'Income Statement'!F8/365 -> 115.76165 | G13: =Assumptions!B50*'Income Statement'!G8/365 -> 123.34983 | H13: =Assumptions!B50*'Income Statement'!H8/365 -> 130.18958 | I13: =Assumptions!B50*'Income Statement'!I8/365 -> 136.75113
A14: Accounts Payable (Days × Rev/365) | B14: =-Assumptions!B49*'Income Statement'!B8/365 -> -620.56849 | C14: =-Assumptions!B49*'Income Statement'!C8/365 -> -771.20137 | D14: =-Assumptions!B49*'Income Statement'!D8/365 -> -884.40411 | E14: =-Assumptions!B49*'Income Statement'!E8/365 -> -964.05558 | F14: =-Assumptions!B49*'Income Statement'!F8/365 -> -1041.8549 | G14: =-Assumptions!B49*'Income Statement'!G8/365 -> -1110.1484 | H14: =-Assumptions!B49*'Income Statement'!H8/365 -> -1171.7062 | I14: =-Assumptions!B49*'Income Statement'!I8/365 -> -1230.7602
A15: Net Working Capital Balance | B15: =B12+B13+B14 -> -303.38904 | C15: =C12+C13+C14 -> -377.03178 | D15: =D12+D13+D14 -> -432.37534 | E15: =E12+E13+E14 -> -471.31606 | F15: =F12+F13+F14 -> -509.35127 | G15: =G12+G13+G14 -> -542.73924 | H15: =H12+H13+H14 -> -572.83413 | I15: =I12+I13+I14 -> -601.70497
A16: Change in NWC | B16: — | C16: =-(C15-B15) -> 73.64274 | D16: =-(D15-C15) -> 55.343562 | E16: =-(E15-D15) -> 38.940717 | F16: =-(F15-E15) -> 38.035206 | G16: =-(G15-F15) -> 33.387975 | H16: =-(H15-G15) -> 30.094891 | I16: =-(I15-H15) -> 28.87084
A17: FREE CASH FLOW TO FIRM (FCFF) | B17: — | C17: =C8+C9+C10+C16 -> 246.74274 | D17: =D8+D9+D10+D16 -> 280.94356 | E17: =E8+E9+E10+E16 -> 1641.9509 | F17: =F8+F9+F10+F16 -> 1833.7878 | G17: =G8+G9+G10+G16 -> 1946.8522 | H17: =H8+H9+H10+H16 -> 2049.6607 | I17: =I8+I9+I10+I16 -> 2150.2227
A19: CAPEX ANALYSIS
A20: Capex as % Revenue | B20: =-193.9/5033.5 -> -0.038521903 | C20: =-403.9/6255.3 -> -0.064569245 | D20: =-391.4/7173.5 -> -0.054561929 | E20: =E10/'Income Statement'!E8 -> -0.056 | F20: =F10/'Income Statement'!F8 -> -0.056 | G20: =G10/'Income Statement'!G8 -> -0.056 | H20: =H10/'Income Statement'!H8 -> -0.056 | I20: =I10/'Income Statement'!I8 -> -0.056
A21: Capex / D&A (>1 = growth capex) | B21: =ABS(B10)/B9 -> 1.0469762 | C21: =ABS(C10)/C9 -> 1.6233923 | D21: =ABS(D10)/D9 -> 1.3874513 | E21: =ABS(E10)/E9 -> 1.4358974 | F21: =ABS(F10)/F9 -> 1.4358974 | G21: =ABS(G10)/G9 -> 1.4358974 | H21: =ABS(H10)/H9 -> 1.4358974 | I21: =ABS(I10)/I9 -> 1.4358974

Sheet DCF Valuation
A1: JET2 PLC — DCF VALUATION (£m)
A2: FCFF discounted at WACC | Gordon Growth terminal value | EV bridge to equity value
B4: FY2026E | C4: FY2027E | D4: FY2028E | E4: FY2029E | F4: FY2030E | G4: Terminal | H4: Total
A5: DISCOUNTED CASH FLOWS
A6: FCFF (£m) | B6: ='Cash Flow'!E17 -> 1641.9509 | C6: ='Cash Flow'!F17 -> 1833.7878 | D6: ='Cash Flow'!G17 -> 1946.8522 | E6: ='Cash Flow'!H17 -> 2049.6607 | F6: ='Cash Flow'!I17 -> 2150.2227 | G6: — | H6: —
A7: Period (t) | B7: 1 | C7: 2 | D7: 3 | E7: 4 | F7: 5 | G7: 5
A8: Discount Factor [1/(1+WACC)^t] | B8: =1/(1+WACC!B21)^B7 -> 0.92210091 | C8: =1/(1+WACC!B21)^C7 -> 0.8502701 | D8: =1/(1+WACC!B21)^D7 -> 0.78403483 | E8: =1/(1+WACC!B21)^E7 -> 0.72295924 | F8: =1/(1+WACC!B21)^F7 -> 0.66664137 | G8: —
A9: PV of FCFF (£m) | B9: =B6*B8 -> 1514.0444 | C9: =C6*C8 -> 1559.2149 | D9: =D6*D8 -> 1526.3999 | E9: =E6*E8 -> 1481.8211 | F9: =F6*F8 -> 1433.4274 | G9: — | H9: =SUM(B9:F9) -> 7514.9079
A11: TERMINAL VALUE (Gordon Growth Method)
A12: Terminal FCFF (FY2030 × (1+g)) | B12: =F6*(1+Assumptions!B54) -> 2203.9783 | C12: FCFFn x (1+g)
A13: WACC | B13: =WACC!B21 -> 0.08448 | C13: From WACC tab
A14: Terminal Growth Rate (g) | B14: =Assumptions!B54 -> 0.025 | C14: From Assumptions tab
A15: Terminal Value [TV = FCFFn+1 / (WACC − g)] | B15: =B12/(B13-B14) -> 37054.108
A16: PV of Terminal Value [TV / (1+WACC)^5] | B16: =B15/(1+WACC!B21)^5 -> 24701.801
A18: ENTERPRISE VALUE BRIDGE
A19: Sum of PV of FCFFs (FY2026–30) | B19: =H9 -> 7514.9079
A20: PV of Terminal Value | B20: =B16 -> 24701.801
A21: Enterprise Value (EV) | B21: =B20+B19 -> 32216.709
A23: Less: Net Debt / Add: Net Cash | B23: =Assumptions!B56 -> 623.6
A24: Equity Value | B24: =B21+B23 -> 32840.309
A25: Shares Outstanding (m) | B25: =Assumptions!B57 -> 203.2
A26: Implied Share Price (£) | B26: =B24/B25 -> 161.61569
A27: Current Share Price (£) | B27: =Assumptions!B58 -> 12.6
A28: Implied Upside / (Downside) | B28: =(B26-B27)/B27 -> 11.826642
A31: VALUATION METRICS & CHECKS
A32: TV as % of Enterprise Value | B32: =B16/B21 -> 0.76673881 | C32: Target: 50–80% (typical aviation)
A33: EV / FY2025A Revenue (x) | B33: =B21/7173.5 -> 4.4910726 | C33: Peer range: 0.4–0.8x
A34: EV / FY2025A EBITDA (x) | B34: =B21/728.6 -> 44.217278 | C34: Peer range: 4–8x
A35: Implied P/E (FY2025A) | B35: =B26/2.2 -> 73.461679 | C35: EPS FY25A est. ~£2.20
A36: WACC − g (Terminal spread) | B36: =WACC!B21-Assumptions!B54 -> 0.05948 | C36: Should be >3% to avoid TV explosion

Sheet Sensitivity
A1: SENSITIVITY ANALYSIS — IMPLIED SHARE PRICE (£)
A2: Green = above current price £12.60 | Red = below | Amber = base case (WACC 9.0%, TGR 2.5%)
A4: TABLE 1: WACC vs Terminal Growth Rate
A5: WACC \ TGR | B5: 0.015 | C5: 0.02 | D5: 0.025 | E5: 0.03 | F5: 0.035
A6: 0.075 | B6: 25.3 | C6: 26.94 | D6: 28.92 | E6: 31.34 | F6: 34.36
A7: 0.08 | B7: 23.55 | C7: 24.91 | D7: 26.53 | E7: 28.47 | F7: 30.84
A8: 0.085 | B8: 22.05 | C8: 23.2 | D8: 24.54 | E8: 26.13 | F8: 28.03
A9: 0.09 | B9: 20.75 | C9: 21.73 | D9: 22.86 | E9: 24.18 | F9: 25.74
A10: 0.095 | B10: 19.61 | C10: 20.46 | D10: 21.42 | E10: 22.53 | F10: 23.82
A11: 0.1 | B11: 18.61 | C11: 19.34 | D11: 20.17 | E11: 21.11 | F11: 22.2
A14: TABLE 2: WACC vs EBIT Margin (FY2026E)
A15: WACC \ EBIT Mg | B15: 0.05 | C15: 0.055 | D15: 0.06 | E15: 0.066 | F15: 0.07 | G15: 0.075
A16: 0.075 | B16: 18.2 | C16: 21.55 | D16: 24.9 | E16: 28.92 | F16: 31.6 | G16: 34.95
A17: 0.08 | B17: 16.8 | C17: 19.84 | D17: 22.88 | E17: 26.53 | F17: 28.96 | G17: 32.01
A18: 0.085 | B18: 15.63 | C18: 18.42 | D18: 21.2 | E18: 24.54 | F18: 26.77 | G18: 29.55
A19: 0.09 | B19: 14.65 | C19: 17.21 | D19: 19.78 | E19: 22.86 | F19: 24.91 | G19: 27.48
A20: 0.095 | B20: 13.8 | C20: 16.18 | D20: 18.56 | E20: 21.42 | F20: 23.32 | G20: 25.7
A21: 0.1 | B21: 13.07 | C21: 15.29 | D21: 17.51 | E21: 20.17 | F21: 21.94 | G21: 24.16
A24: Note: Amber = base case | Green = above current price £12.60 | Red = below

Sheet Scenarios
A1: SCENARIO ANALYSIS — JET2 PLC
A2: Base | Bull | Bear — key assumptions and valuation outputs
A4: ASSUMPTION | B4: BASE CASE | C4: BULL CASE | D4: BEAR CASE
A5: Revenue CAGR (FY25–30) | B5: ~6.5% | C5: ~8.5% | D5: ~4.5%
A6: EBIT Margin FY2030E | B6: 7.2% | C6: 8.5% | D6: 5.5%
A7: WACC | B7: 9.0% | C7: 8.0% | D7: 10.0%
A8: Terminal Growth Rate | B8: 2.5% | C8: 3.0% | D8: 2.0%
A9: Capex % Revenue | B9: 5.6% | C9: 5.0% | D9: 7.0%
A11: Implied Share Price (£) | B11: £22.18 | C11: £47.26 | D11: £5.68
A12: EV (£m) | B12: £3,884m | C12: £8,981m | D12: £531m
A13: Upside / (Downside) | B13: 76.0% | C13: 275.1% | D13: -54.9%

Sheet Comparables
A1: COMPARABLE COMPANY ANALYSIS — EUROPEAN LEISURE & LOW-COST AIRLINES
A2: Source: Yahoo Finance / public filings, March 2026 estimates | NTM = Next Twelve Months
A4: Company | B4: EV (£m) | C4: Rev (£m) | D4: EBITDA (£m) | E4: EV/Rev | F4: EV/EBITDA | G4: P/E | H4: Note
A5: Ryanair Holdings | B5: 18200 | C5: 14800 | D5: 4100 | E5: =B5/C5 -> 1.2297297 | F5: =B5/D5 -> 4.4390244 | G5: n/m | H5: ULCC; highest margins in sector
A6: easyJet plc | B6: 5800 | C6: 7200 | D6: 1150 | E6: =B6/C6 -> 0.80555556 | F6: =B6/D6 -> 5.0434783 | G6: n/m | H6: UK LCC; comparable leisure focus
A7: Wizz Air Holdings | B7: 3200 | C7: 5100 | D7: 820 | E7: =B7/C7 -> 0.62745098 | F7: =B7/D7 -> 3.902439 | G7: n/m | H7: CEE-focused ULCC
A8: TUI AG | B8: 4900 | C8: 8800 | D8: 950 | E8: =B8/C8 -> 0.55681818 | F8: =B8/D8 -> 5.1578947 | G8: n/m | H8: Integrated tour operator; closest peer
A9: Int'l Airlines Group | B9: 11500 | C9: 11200 | D9: 2600 | E9: =B9/C9 -> 1.0267857 | F9: =B9/D9 -> 4.4230769 | G9: n/m | H9: BA/Iberia; legacy; diff. model
A11: Peer Median | B11: — | C11: — | D11: — | E11: =MEDIAN(E5,E6,E7,E8,E9) -> 0.80555556 | F11: =MEDIAN(F5,F6,F7,F8,F9) -> 4.4390244 | G11: —
A12: Peer Mean | B12: — | C12: — | D12: — | E12: =AVERAGE(E5,E6,E7,E8,E9) -> 0.84926803 | F12: =AVERAGE(F5,F6,F7,F8,F9) -> 4.5931827 | G12: —
A14: JET2 PLC (DCF implied) | B14: → DCF | C14: 7174 | D14: 729 | E14: → DCF | F14: → DCF | G14: → DCF | H14: Our DCF valuation
A17: Note: All figures in £m. EV and estimates sourced from Yahoo Finance / public filings. Jet2 figures from FY2025A annual report.

Sheet Model Checks
A1: MODEL INTEGRITY CHECKS
A2: All checks should show ✓ PASS | Red = error requiring investigation
A4: CHECK | B4: Value | C4: Status | D4: Threshold
A5: WACC > Terminal Growth Rate (prevents TV explosion) | B5: =WACC!B21-Assumptions!B54 -> 0.05948 | C5: =IF(B5>0,"✓ PASS","✗ FAIL") -> ✓ PASS | D5: >0 required
A6: Terminal Value as % of EV (50–80% is standard) | B6: ='DCF Valuation'!B16/'DCF Valuation'!B21 -> 0.76673881 | C6: =IF(AND(B6>0.4,B6<0.9),"✓ PASS","⚠ REVIEW") -> ✓ PASS | D6: 40–90% acceptable
A7: Equity Weights Sum to 100% | B7: =WACC!B16+WACC!B17 -> 1 | C7: =IF(ABS(B7-1)<0.001,"✓ PASS","✗ FAIL") -> ✓ PASS | D7: Must equal 1.00x
A8: FCFF Positive in Forecast Period (FY2026E+) | B8: =MIN('Cash Flow'!E17,'Cash Flow'!F17,'Cash Flow'!G17,'Cash Flow'!H17,'Cash Flow'!I17) -> 1641.9509 | C8: =IF(B8>0,"✓ PASS","⚠ REVIEW") -> ✓ PASS | D8: >0 required
A9: Revenue Growing (FY26 > FY25) | B9: ='Income Statement'!E8-'Income Statement'!D8 -> 646.0619 | C9: =IF(B9>0,"✓ PASS","✗ FAIL") -> ✓ PASS | D9: >0 required
A10: Capex > D&A (growth capex — expected for Jet2) | B10: =ABS('Cash Flow'!E10)/'Cash Flow'!E9 -> 1.4358974 | C10: =IF(B10>1,"✓ PASS","⚠ REVIEW") -> ✓ PASS | D10: >1.0x expected
A11: Implied Share Price Positive | B11: ='DCF Valuation'!B26 -> 161.61569 | C11: =IF(B11>0,"✓ PASS","✗ FAIL") -> ✓ PASS | D11: >0 required
A12: WACC in Reasonable Range (7–12%) | B12: =WACC!B21 -> 0.08448 | C12: =IF(AND(B12>0.07,B12<0.12),"✓ PASS","⚠ REVIEW") -> ✓ PASS | D12: 7–12% expected

Sheet Investment Memo
A1: INVESTMENT MEMO — JET2 PLC (LON: JET2)
A2: Prepared by: Yassin Al-Yassin | Date: Jan 2026 | Methodology: 5-year FCFF DCF, Gordon Growth TV, Comps cross-check
A4: COMPANY
A5: Business | B5: Jet2 plc is the UK's leading vertically integrated leisure travel group, operating Jet2.com (scheduled flights) and Jet2holidays (ATOL-licensed package tours). The group carries 22.3m passengers p.a. to Mediterranean, Canary Islands and European city destinations from 10 UK bases. Listed on AIM (LON: JET2). FY2025A revenue: £7.2bn.
A6: Recent Performance | B6: Revenue CAGR of 19% over 3 years (FY22–25) driven by post-COVID demand recovery and strategic capacity expansion. EBIT has grown from £394m to £447m despite fuel headwinds. Net cash position of £624m at FY25 year-end provides balance sheet resilience.
A8: INVESTMENT THESIS
A9: Thesis Statement | B9: Jet2 offers a differentiated, execution-driven leisure travel model with structural tailwinds. The business is vertically integrated, highly cash generative, and is investing in long-term capacity via a 146 A321neo order (through 2035) that will drive unit cost reduction. The stock appears undervalued relative to DCF intrinsic value.
A10: Key Bull Points | B10: 1. Structural shift to package holidays post-COVID benefits Jet2holidays (72% of passengers). 2. A321neo fleet (more fuel-efficient, larger seats) drives 15–18% unit cost improvement per seat. 3. Net cash balance of £624m provides downside protection, funds capex, and enables opportunistic capacity deployment. 4. Management track record, consistent execution, no profit warnings, conservative guidance. 5. UK leisure travel structurally underpenetrated vs. European peers.
A11: Key Bear Points | B11: 1. Aviation is highly cyclical: fuel price spikes, FX (USD costs, GBP revenues), and consumer confidence all drive earnings volatility. 2. Capex intensity rising with A321neo deliveries, FCF conversion may be suppressed through FY2027–28. 3. Competitive pressure from easyJet, TUI, and online travel aggregators. 4. Regulatory and ESG costs increasing: SAF blending mandates, carbon pricing, and APD risk. 5. Rising IFRS 16 lease liabilities on balance sheet.
A13: VALUATION
A14: Methodology | B14: 5-year FCFF discounted cash flow model. WACC built using CAPM (Rf = 4.3%, β = 1.25, ERP = 5.5%). Terminal value calculated using Gordon Growth perpetuity method (g = 2.5%). EV bridged to equity value using FY2025A net cash of £624m and 203.2m diluted shares outstanding.
A15: Key Assumptions | B15: Revenue driven by seats flown × average revenue per seat. EBIT margin expands from 6.6% (FY26E) to 7.2% (FY30E) as A321neo cost savings materialise. Capex at 5.6% of revenue; D&A at 3.9%. Base case WACC: ~9.0%.
A16: Cross-Check | B16: Peer EV/EBITDA range: 4–8x. Peer EV/Revenue range: 0.4–0.8x. Our implied multiples should be benchmarked against the Comparables tab to ensure valuation is anchored in market reality, not just model assumptions.
A17: Sensitivity | B17: Sensitivity analysis shows the valuation is most sensitive to WACC and terminal growth rate. See Sensitivity tab for full WACC × TGR matrix and WACC × EBIT margin matrix.
A19: KEY RISKS
A20: Macro / Cyclical | B20: Recession risk reducing discretionary travel; oil price spike (Jet2 partially hedged); GBP weakness increasing USD-denominated costs (fuel, leases).
A21: Regulatory | B21: Carbon pricing escalation; SAF blending mandate costs (est. 2–5% revenue impact by 2030); Air Passenger Duty increases.
A22: Operational | B22: Airspace congestion and ATC strike risk; aircraft delivery delays from Airbus; IT failure at peak booking season.
A23: Financial | B23: Lease liability growth under IFRS 16; refinancing risk on maturing debt facilities; covenant headroom under stress scenario.
A25: CONCLUSION
A26: Recommendation | B26: Subject to sensitivity and scenario outcomes — see DCF Valuation and Sensitivity tabs. The base case implies [see DCF tab for live implied price]. The investment case rests on continued execution of capacity growth, A321neo cost delivery, and resilience of UK leisure demand.
A28: DATA SOURCES
A29: Sources | B29: Jet2 plc Annual Reports FY2023, FY2024, FY2025 | Jet2 Preliminary Results announcements | Yahoo Finance (share price, peer data) | Damodaran Online (beta, ERP) | UK DMO (risk-free rate) | Company investor relations materials
