Workbook

Sheet Dashboard
A1: PETS AT HOME LBO — DEAL DASHBOARD
A2: All outputs linked live from model | Analyst: Yassin Al-Yassin | Dec 2026
A4: TRANSACTION SUMMARY
A5: Entry EV (£m) | B5: =Assumptions!B11 -> 1890
A6: Entry EV / EBITDA | B6: =Assumptions!B9 -> 7.5
A7: Sponsor Equity (£m) | B7: =Assumptions!B26 -> 760.35
A8: TLA (£m) | B8: =Assumptions!B36 -> 680
A9: TLB (£m) | B9: =Assumptions!B39 -> 453
A10: Total Debt at Entry (£m) | B10: =Assumptions!B36+Assumptions!B39 -> 1133
A11: Debt / EBITDA at Entry | B11: =(Assumptions!B36+Assumptions!B39)/Assumptions!B10 -> 4.4960317
A12: Equity % | B12: =(Assumptions!B26+Assumptions!B19)/(Assumptions!B36+Assumptions!B39+Assumptions!B26+Assumptions!B19) -> 0.40938828
A14: RETURNS SUMMARY
A15: Exit Enterprise Value (£m) | B15: ='Cash Flow & Returns'!B18 -> 2716.5102
A16: Exit EV / EBITDA (x) | B16: =Assumptions!B18 -> 8
A17: Net Debt at Exit (£m) | B17: ='Debt Schedule'!F19 -> 807.08325
A18: Exit Equity Value (£m) | B18: ='Cash Flow & Returns'!B20 -> 1909.4269
A19: Sponsor Proceeds (£m) | B19: ='Cash Flow & Returns'!B24 -> 1848.6443
A20: MoM Multiple | B20: ='Cash Flow & Returns'!B25 -> 2.431307
A21: IRR (5yr hold) | B21: ='Cash Flow & Returns'!B26 -> 0.19444996
A24: NAVIGATION
A25: Assumptions | B25: Transaction, S&U, debt & operating assumptions
A26: Income Statement | B26: P&L projection FY2024A–FY2030E
A27: Debt Schedule | B27: TLA/TLB amortisation + cash sweep
A28: Cash Flow & Returns | B28: FCFE, exit analysis, IRR & MoM
A29: Sensitivity | B29: IRR & MoM across entry/exit multiples
A30: Comparables | B30: UK pet care & specialist retail comps
A31: Investment Memo | B31: Full deal memo with thesis, risks, valuation

Sheet Assumptions
A1: PETS AT HOME GROUP PLC — LBO MODEL ASSUMPTIONS
A2: Blue = input | Black = formula | Green = cross-sheet | Source: Pets at Home Annual Reports FY2024–FY2025
A4: Blue = Hardcoded input
A5: Black = Formula
A6: Green = Cross-sheet
A8: TRANSACTION ASSUMPTIONS
A9: Entry EV / EBITDA (x) | B9: 7.5 | C9: Source: UK pet care M&A comps; THL/Pets@Home precedent
A10: LTM EBITDA at Entry (£m) | B10: 252 | C10: FY2025A EBITDA; Source: Pets at Home FY25 Annual Report
A11: Entry Enterprise Value (£m) | B11: =B9*B10 -> 1890 | C11: Entry EV/EBITDA x LTM EBITDA
A12: Entry Equity Value (£m) | C12: EV minus Total Debt at Entry
A13: Transaction Fees % EV | B13: 0.015 | C13: M&A advisory, legal, financing fees
A14: Transaction Fees (£m) | B14: =B11*B13 -> 28.35 | C14: Entry EV x fees pct
A15: Total Sources = Uses (£m) | C15: Verification check
A17: Exit Year (from entry) | B17: 5 | C17: Standard PE hold period
A18: Exit EV / EBITDA (x) | B18: 8 | C18: Modest multiple expansion on execution
A19: Management Rollover (£m) | B19: 25 | C19: Mgmt equity retained
A21: SOURCES & USES (£m)
A22: SOURCES
A23: Senior Secured (Term Loan A) | B23: 680 | C23: ~2.7x EBITDA; floating rate SONIA+400bps
A24: Senior Secured (Term Loan B) | B24: 453 | C24: ~1.8x EBITDA; SONIA+500bps; PIK toggle
A25: Revolving Credit Facility | B25: 0 | C25: £150m RCF, undrawn at close
A26: Sponsor Equity | B26: =B33-B23-B24-B25-B27 -> 760.35 | C26: Residual = EV + fees − debt
A27: Management Rollover | B27: =B19 -> 25 | C27: Linked from above
A28: Total Sources | B28: =B23+B24+B25+B26+B27 -> 1918.35
A30: USES
A31: Purchase of Equity (EV) | B31: =B11 -> 1890 | C31: Entry Enterprise Value
A32: Transaction Fees | B32: =B14 -> 28.35 | C32: Fees from above
A33: Total Uses | B33: =B31+B32 -> 1918.35 | C33: Must equal Total Sources
A35: DEBT ASSUMPTIONS
A36: TLA Opening Balance (£m) | B36: 680 | C36: At close; ~2.7x EBITDA
A37: TLA Interest Rate (SONIA+spread) | B37: 0.092 | C37: SONIA 5.2% + 400bps margin
A38: TLA Annual Amortisation % | B38: 0.1 | C38: 10% annual mandatory amortisation
A39: TLB Opening Balance (£m) | B39: 453 | C39: At close; ~1.8x EBITDA
A40: TLB Interest Rate | B40: 0.102 | C40: SONIA 5.2% + 500bps margin
A41: TLB Annual Amortisation % | B41: 0.01 | C41: 1% p.a. (bullet at exit)
A42: Cash Sweep % of Excess Cash | B42: 0.5 | C42: 50% cash sweep applied to TLA first
A43: Minimum Cash Balance (£m) | B43: 30 | C43: Operational minimum
A45: OPERATING ASSUMPTIONS
A46: Revenue FY2025A (£m) | B46: 1674 | C46: Source: Pets at Home FY25 Annual Report, p.4
A47: Revenue Growth FY2026E | B47: 0.045 | C47: Store rollout + vet practice maturation
...

Sheet Income Statement
A1: PETS AT HOME GROUP PLC — INCOME STATEMENT (£m)
A2: Gray = Historical | Blue = Forecast | Source: Pets at Home Annual Reports
B4: FY2024A | C4: FY2025A | D4: FY2026E | E4: FY2027E | F4: FY2028E | G4: FY2029E | H4: FY2030E
A5: P&L
A6: Revenue | B6: 1598 | C6: 1674 | D6: =C6*(1+Assumptions!B47) -> 1749.33 | E6: =D6*(1+Assumptions!B48) -> 1836.7965 | F6: =E6*(1+Assumptions!B49) -> 1924.9627 | G6: =F6*(1+Assumptions!B50) -> 2011.5861 | H6: =G6*(1+Assumptions!B51) -> 2096.0727
A7: YoY Growth | B7: — | C7: =(C6-B6)/B6 -> 0.047559449 | D7: =(D6-C6)/C6 -> 0.045 | E7: =(E6-D6)/D6 -> 0.05 | F7: =(F6-E6)/E6 -> 0.048 | G7: =(G6-F6)/F6 -> 0.045 | H7: =(H6-G6)/G6 -> 0.042
A8: EBITDA | B8: 236.504 | C8: 252.2718 | D8: =D6*Assumptions!B53 -> 265.89816 | E8: =E6*Assumptions!B54 -> 284.70346 | F8: =F6*Assumptions!B55 -> 304.14411 | G8: =G6*Assumptions!B56 -> 321.85377 | H8: =H6*Assumptions!B57 -> 339.56377
A9: EBITDA Margin | B9: =B8/B6 -> 0.148 | C9: =C8/C6 -> 0.1507 | D9: =D8/D6 -> 0.152 | E9: =E8/E6 -> 0.155 | F9: =F8/F6 -> 0.158 | G9: =G8/G6 -> 0.16 | H9: =H8/H6 -> 0.162
A10: Depreciation & Amortisation | B10: -59.8 | C10: -63.6 | D10: =-D6*Assumptions!B58 -> -66.47454 | E10: =-E6*Assumptions!B58 -> -69.798267 | F10: =-F6*Assumptions!B58 -> -73.148584 | G10: =-G6*Assumptions!B58 -> -76.44027 | H10: =-H6*Assumptions!B58 -> -79.650761
A11: EBIT | B11: =B8+B10 -> 176.704 | C11: =C8+C10 -> 188.6718 | D11: =D8+D10 -> 199.42362 | E11: =E8+E10 -> 214.90519 | F11: =F8+F10 -> 230.99553 | G11: =G8+G10 -> 245.4135 | H11: =H8+H10 -> 259.91301
A12: EBIT Margin | B12: =B11/B6 -> 0.11057822 | C12: =C11/C6 -> 0.11270717 | D12: =D11/D6 -> 0.114 | E12: =E11/E6 -> 0.117 | F12: =F11/F6 -> 0.12 | G12: =G11/G6 -> 0.122 | H12: =H11/H6 -> 0.124
A14: BELOW THE LINE
A15: Interest Expense (TLA) | B15: 0 | C15: 0 | D15: ='Debt Schedule'!B9 -> -59.432 | E15: ='Debt Schedule'!C9 -> -53.4888 | F15: ='Debt Schedule'!D9 -> -48.13992 | G15: ='Debt Schedule'!E9 -> -43.325928 | H15: ='Debt Schedule'!F9 -> -38.292525
A16: Interest Expense (TLB) | B16: 0 | C16: 0 | D16: ='Debt Schedule'!B15 -> -45.97497 | E16: ='Debt Schedule'!C15 -> -45.51522 | F16: ='Debt Schedule'!D15 -> -45.060068 | G16: ='Debt Schedule'!E15 -> -44.609467 | H16: ='Debt Schedule'!F15 -> -44.163373
A17: Total Interest Expense | B17: =B15+B16 -> 0 | C17: =C15+C16 -> 0 | D17: =D15+D16 -> -105.40697 | E17: =E15+E16 -> -99.00402 | F17: =F15+F16 -> -93.199988 | G17: =G15+G16 -> -87.935395 | H17: =H15+H16 -> -82.455898
A18: Tax | B18: -37 | C18: -37 | D18: =-MAX((D11+D17)*Assumptions!B61,0) -> -23.504162 | E18: =-MAX((E11+E17)*Assumptions!B61,0) -> -28.975293 | F18: =-MAX((F11+F17)*Assumptions!B61,0) -> -34.448885 | G18: =-MAX((G11+G17)*Assumptions!B61,0) -> -39.369526 | H18: =-MAX((H11+H17)*Assumptions!B61,0) -> -44.364278
A19: Net Income / (Loss) | B19: 138.6 | C19: 147.2 | D19: =D11+D17+D18 -> 70.512487 | E19: =E11+E17+E18 -> 86.925878 | F19: =F11+F17+F18 -> 103.34665 | G19: =G11+G17+G18 -> 118.10858 | H19: =H11+H17+H18 -> 133.09283

Sheet Debt Schedule
A1: DEBT SCHEDULE & CASH SWEEP (£m)
A2: Mandatory amortisation + 50% excess cash sweep | Interest on average balances
B4: FY2026E | C4: FY2027E | D4: FY2028E | E4: FY2029E | F4: FY2030E
A5: TERM LOAN A
A6: Opening Balance (£m) | B6: =Assumptions!B36 -> 680 | C6: =B10 -> 612 | D6: =C10 -> 550.8 | E6: =D10 -> 495.72 | F6: =E10 -> 438.12958
A7: Mandatory Amortisation (£m) | B7: =-B6*Assumptions!B38 -> -68 | C7: =-C6*Assumptions!B38 -> -61.2 | D7: =-D6*Assumptions!B38 -> -55.08 | E7: =-E6*Assumptions!B38 -> -49.572 | F7: =-F6*Assumptions!B38 -> -43.812958
A8: Cash Sweep (£m) | B8: =B31 -> 0 | C8: =C31 -> 0 | D8: =D31 -> 0 | E8: =E31 -> -8.0184243 | F8: =F31 -> -18.031862
A9: Interest Expense (£m) | B9: =-((B6+B6+B7)/2)*Assumptions!B37 -> -59.432 | C9: =-((C6+C6+C7)/2)*Assumptions!B37 -> -53.4888 | D9: =-((D6+D6+D7)/2)*Assumptions!B37 -> -48.13992 | E9: =-((E6+E6+E7)/2)*Assumptions!B37 -> -43.325928 | F9: =-((F6+F6+F7)/2)*Assumptions!B37 -> -38.292525
A10: Closing Balance (£m) | B10: =B6+B7+B8 -> 612 | C10: =C6+C7+C8 -> 550.8 | D10: =D6+D7+D8 -> 495.72 | E10: =E6+E7+E8 -> 438.12958 | F10: =F6+F7+F8 -> 376.28476
A12: TERM LOAN B
A13: Opening Balance (£m) | B13: =Assumptions!B39 -> 453 | C13: =B16 -> 448.47 | D13: =C16 -> 443.9853 | E13: =D16 -> 439.54545 | F13: =E16 -> 435.14999
A14: Mandatory Amortisation (£m) | B14: =-B13*Assumptions!B41 -> -4.53 | C14: =-C13*Assumptions!B41 -> -4.4847 | D14: =-D13*Assumptions!B41 -> -4.439853 | E14: =-E13*Assumptions!B41 -> -4.3954545 | F14: =-F13*Assumptions!B41 -> -4.3514999
A15: Interest Expense (£m) | B15: =-((B13+B13+B14)/2)*Assumptions!B40 -> -45.97497 | C15: =-((C13+C13+C14)/2)*Assumptions!B40 -> -45.51522 | D15: =-((D13+D13+D14)/2)*Assumptions!B40 -> -45.060068 | E15: =-((E13+E13+E14)/2)*Assumptions!B40 -> -44.609467 | F15: =-((F13+F13+F14)/2)*Assumptions!B40 -> -44.163373
A16: Closing Balance (£m) | B16: =B13+B14 -> 448.47 | C16: =C13+C14 -> 443.9853 | D16: =D13+D14 -> 439.54545 | E16: =E13+E14 -> 435.14999 | F16: =F13+F14 -> 430.79849
A18: TOTAL DEBT SUMMARY
A19: Total Debt Closing (£m) | B19: =B10+B16 -> 1060.47 | C19: =C10+C16 -> 994.7853 | D19: =D10+D16 -> 935.26545 | E19: =E10+E16 -> 873.27957 | F19: =F10+F16 -> 807.08325
A20: Total Interest Expense (£m) | B20: =B9+B15 -> -105.40697 | C20: =C9+C15 -> -99.00402 | D20: =D9+D15 -> -93.199988 | E20: =E9+E15 -> -87.935395 | F20: =F9+F15 -> -82.455898
A21: Net Debt / EBITDA (x) | B21: =B19/'Income Statement'!D8 -> 3.9882563 | C21: =C19/'Income Statement'!E8 -> 3.4941104 | D21: =D19/'Income Statement'!F8 -> 3.0750733 | E21: =E19/'Income Statement'!G8 -> 2.7132805 | F21: =F19/'Income Statement'!H8 -> 2.3768238
A23: CASH SWEEP CALCULATION
A24: EBITDA (£m) | B24: ='Income Statement'!D8 -> 265.89816 | C24: ='Income Statement'!E8 -> 284.70346 | D24: ='Income Statement'!F8 -> 304.14411 | E24: ='Income Statement'!G8 -> 321.85377 | F24: ='Income Statement'!H8 -> 339.56377
A25: Less: Cash Interest (£m) | B25: =B20 -> -105.40697 | C25: =C20 -> -99.00402 | D25: =D20 -> -93.199988 | E25: =E20 -> -87.935395 | F25: =F20 -> -82.455898
A26: Less: Tax (£m) | B26: ='Income Statement'!D18 -> -23.504162 | C26: ='Income Statement'!E18 -> -28.975293 | D26: ='Income Statement'!F18 -> -34.448885 | E26: ='Income Statement'!G18 -> -39.369526 | F26: ='Income Statement'!H18 -> -44.364278
A27: Less: Capex (£m) | B27: =-'Income Statement'!D6*Assumptions!B59 -> -73.47186 | C27: =-'Income Statement'!E6*Assumptions!B59 -> -77.145453 | D27: =-'Income Statement'!F6*Assumptions!B59 -> -80.848435 | E27: =-'Income Statement'!G6*Assumptions!B59 -> -84.486614 | F27: =-'Income Statement'!H6*Assumptions!B59 -> -88.035052
A28: Less: Change in NWC (£m) | B28: ='Income Statement'!D6*Assumptions!B60 -> -8.74665 | C28: ='Income Statement'!E6*Assumptions!B60 -> -9.1839825 | D28: ='Income Statement'!F6*Assumptions!B60 -> -9.6248137 | E28: ='Income Statement'!G6*Assumptions!B60 -> -10.05793 | F28: ='Income Statement'!H6*Assumptions!B60 -> -10.480363
A29: Less: Mandatory Amortisation (£m) | B29: =B7+B14 -> -72.53 | C29: =C7+C14 -> -65.6847 | D29: =D7+D14 -> -59.519853 | E29: =E7+E14 -> -53.967454 | F29: =F7+F14 -> -48.164458
A30: Excess Cash Available for Sweep (£m) | B30: =MAX(B24+B25+B26+B27+B28+B29-Assumptions!B43,0) -> 0 | C30: =MAX(C24+C25+C26+C27+C28+C29-Assumptions!B43,0) -> 0 | D30: =MAX(D24+D25+D26+D27+D28+D29-Assumptions!B43,0) -> 0 | E30: =MAX(E24+E25+E26+E27+E28+E29-Assumptions!B43,0) -> 16.036849 | F30: =MAX(F24+F25+F26+F27+F28+F29-Assumptions!B43,0) -> 36.063723
A31: Cash Sweep Applied to TLA (£m) | B31: =-MIN(B30*Assumptions!B42,MAX(B6+B7,0)) -> 0 | C31: =-MIN(C30*Assumptions!B42,MAX(C6+C7,0)) -> 0 | D31: =-MIN(D30*Assumptions!B42,MAX(D6+D7,0)) -> 0 | E31: =-MIN(E30*Assumptions!B42,MAX(E6+E7,0)) -> -8.0184243 | F31: =-MIN(F30*Assumptions!B42,MAX(F6+F7,0)) -> -18.031862

Sheet Cash Flow & Returns
A1: CASH FLOW, EXIT & RETURNS ANALYSIS (£m)
A2: Free Cash Flow to Equity | Exit at Year 5 | IRR & MoM returns
B4: FY2026E | C4: FY2027E | D4: FY2028E | E4: FY2029E | F4: FY2030E
A5: FREE CASH FLOW TO EQUITY
A6: EBITDA (£m) | B6: ='Income Statement'!D8 -> 265.89816 | C6: ='Income Statement'!E8 -> 284.70346 | D6: ='Income Statement'!F8 -> 304.14411 | E6: ='Income Statement'!G8 -> 321.85377 | F6: ='Income Statement'!H8 -> 339.56377
A7: Less: Cash Interest | B7: ='Debt Schedule'!B20 -> -105.40697 | C7: ='Debt Schedule'!C20 -> -99.00402 | D7: ='Debt Schedule'!D20 -> -93.199988 | E7: ='Debt Schedule'!E20 -> -87.935395 | F7: ='Debt Schedule'!F20 -> -82.455898
A8: Less: Tax | B8: ='Income Statement'!D18 -> -23.504162 | C8: ='Income Statement'!E18 -> -28.975293 | D8: ='Income Statement'!F18 -> -34.448885 | E8: ='Income Statement'!G18 -> -39.369526 | F8: ='Income Statement'!H18 -> -44.364278
A9: Less: Capex | B9: =-'Income Statement'!D6*Assumptions!B59 -> -73.47186 | C9: =-'Income Statement'!E6*Assumptions!B59 -> -77.145453 | D9: =-'Income Statement'!F6*Assumptions!B59 -> -80.848435 | E9: =-'Income Statement'!G6*Assumptions!B59 -> -84.486614 | F9: =-'Income Statement'!H6*Assumptions!B59 -> -88.035052
A10: Less: Change in NWC | B10: ='Income Statement'!D6*Assumptions!B60 -> -8.74665 | C10: ='Income Statement'!E6*Assumptions!B60 -> -9.1839825 | D10: ='Income Statement'!F6*Assumptions!B60 -> -9.6248137 | E10: ='Income Statement'!G6*Assumptions!B60 -> -10.05793 | F10: ='Income Statement'!H6*Assumptions!B60 -> -10.480363
A11: Less: Mandatory Debt Amortisation | B11: ='Debt Schedule'!B7+'Debt Schedule'!B14 -> -72.53 | C11: ='Debt Schedule'!C7+'Debt Schedule'!C14 -> -65.6847 | D11: ='Debt Schedule'!D7+'Debt Schedule'!D14 -> -59.519853 | E11: ='Debt Schedule'!E7+'Debt Schedule'!E14 -> -53.967454 | F11: ='Debt Schedule'!F7+'Debt Schedule'!F14 -> -48.164458
A12: Less: Cash Sweep | B12: ='Debt Schedule'!B31 -> 0 | C12: ='Debt Schedule'!C31 -> 0 | D12: ='Debt Schedule'!D31 -> 0 | E12: ='Debt Schedule'!E31 -> -8.0184243 | F12: ='Debt Schedule'!F31 -> -18.031862
A13: Free Cash Flow to Equity (£m) | B13: =B6+B7+B8+B9+B10+B11+B12 -> -17.761483 | C13: =C6+C7+C8+C9+C10+C11+C12 -> 4.7100091 | D13: =D6+D7+D8+D9+D10+D11+D12 -> 26.502137 | E13: =E6+E7+E8+E9+E10+E11+E12 -> 38.018424 | F13: =F6+F7+F8+F9+F10+F11+F12 -> 48.031862
A15: EXIT ANALYSIS
A16: Exit Year EBITDA (£m) | B16: ='Income Statement'!H8 -> 339.56377
A17: Exit EV / EBITDA Multiple (x) | B17: =Assumptions!B18 -> 8
A18: Exit Enterprise Value (£m) | B18: =B16*B17 -> 2716.5102
A19: Less: Net Debt at Exit (£m) | B19: =-'Debt Schedule'!F19 -> -807.08325
A20: Exit Equity Value (£m) | B20: =B18+B19 -> 1909.4269
A22: SPONSOR RETURNS
A23: Sponsor Equity Invested (£m) | B23: =Assumptions!B26 -> 760.35
A24: Sponsor Exit Proceeds (£m) | B24: =B20*(Assumptions!B26/(Assumptions!B26+Assumptions!B19)) -> 1848.6443
A25: Money-on-Money Multiple (MoM) | B25: =B24/B23 -> 2.431307
A26: IRR (Approximate — 5yr hold) | B26: =(B24/B23)^(1/Assumptions!B17)-1 -> 0.19444996
A28: CREDIT METRICS AT ENTRY
A29: Total Debt / EBITDA (Entry) | B29: =(Assumptions!B36+Assumptions!B39)/Assumptions!B10 -> 4.4960317
A30: Senior Debt / EBITDA (TLA only) | B30: =Assumptions!B36/Assumptions!B10 -> 2.6984127
A31: Interest Coverage (EBITDA / Interest, Yr1) | B31: ='Income Statement'!E8/ABS('Debt Schedule'!B20) -> 2.7009927
A32: Equity % of Total Capitalisation | B32: =(Assumptions!B26+Assumptions!B19)/(Assumptions!B36+Assumptions!B39+Assumptions!B26+Assumptions!B19) -> 0.40938828

Sheet Sensitivity
A1: SENSITIVITY — IRR & MoM vs ENTRY MULTIPLE & EXIT MULTIPLE
A2: Green = IRR >20% | Amber = 15–20% | Red = <15% | Base case (7.5x entry, 8.0x exit) highlighted
A4: IRR — Entry x \ Exit x | B4: 6.5x | C4: 7.0x | D4: 7.5x | E4: 8.0x | F4: 8.5x | G4: 9.0x | H4: 9.5x
A5: 6.0x | B5: 0.22767885 | C5: 0.25208162 | D5: 0.2747181 | E5: 0.29585228 | F5: 0.31569142 | G5: 0.33440144 | H5: 0.3521174
A6: 6.5x | B6: 0.18034484 | C6: 0.20380674 | D6: 0.22557046 | E6: 0.2458898 | F6: 0.26496402 | G6: 0.28295267 | H6: 0.29998558
A7: 7.0x | B7: 0.14220699 | C7: 0.16491082 | D7: 0.18597134 | E7: 0.20563414 | F7: 0.22409206 | G7: 0.24149948 | H7: 0.25798205
A8: 7.5x | B8: 0.11044258 | C8: 0.13251502 | D8: 0.15298986 | E8: 0.17210584 | F8: 0.19005045 | G8: 0.20697378 | H8: 0.22299797
A9: 8.0x | B9: 0.083335925 | C9: 0.10486956 | D9: 0.12484459 | E9: 0.14349394 | F9: 0.16100051 | G9: 0.17751073 | H9: 0.19314376
A10: 8.5x | B10: 0.059770346 | C10: 0.080835566 | D10: 0.10037608 | E10: 0.11861976 | F10: 0.13574551 | G10: 0.15189659 | H10: 0.16718955
A11: 9.0x | B11: 0.038980537 | C11: 0.059632515 | D11: 0.0787897 | E11: 0.096675484 | F11: 0.11346528 | G11: 0.12929951 | H11: 0.14429247
A14: MoM — Entry x \ Exit x | B14: 6.5x | C14: 7.0x | D14: 7.5x | E14: 8.0x | F14: 8.5x | G14: 9.0x | H14: 9.5x
A15: 6.0x | B15: 2.7888418 | C15: 3.0772529 | D15: 3.3656641 | E15: 3.6540753 | F15: 3.9424864 | G15: 4.2308976 | H15: 4.5193088
A16: 6.5x | B16: 2.2911026 | C16: 2.5280395 | D16: 2.7649764 | E16: 3.0019133 | F16: 3.2388502 | G16: 3.4757872 | H16: 3.7127241
A17: 7.0x | B17: 1.9441245 | C17: 2.1451783 | D17: 2.3462321 | E17: 2.5472859 | F17: 2.7483397 | G17: 2.9493935 | H17: 3.1504473
A18: 7.5x | B18: 1.6884202 | C18: 1.86303 | D18: 2.0376399 | E18: 2.2122497 | F18: 2.3868596 | G18: 2.5614694 | H18: 2.7360793
A19: 8.0x | B19: 1.4921611 | C19: 1.6464746 | D19: 1.8007881 | E19: 1.9551016 | F19: 2.1094151 | G19: 2.2637286 | H19: 2.4180421
A20: 8.5x | B20: 1.3367765 | C20: 1.4750208 | D20: 1.613265 | E20: 1.7515092 | F20: 1.8897535 | G20: 2.0279977 | H20: 2.1662419
A21: 9.0x | B21: 1.2107014 | C21: 1.3359075 | D21: 1.4611135 | E21: 1.5863195 | F21: 1.7115256 | G21: 1.8367316 | H21: 1.9619376
A24: Green = IRR >20% / MoM >2.5x | Gray = 15–20% / 2.0–2.5x | Red = <15% / <2.0x | Amber = base case

Sheet Comparables
A1: COMPARABLE COMPANY ANALYSIS — UK PET CARE & SPECIALIST RETAIL
A2: Source: Yahoo Finance / public filings, Dec 2026 | EV/EBITDA on NTM basis
A4: Company | B4: EV (£m) | C4: Rev (£m) | D4: EBITDA (£m) | E4: EBIT Mg | F4: EV/Rev | G4: EV/EBITDA | H4: Note
A5: Pets at Home (current) | B5: 1850 | C5: 1674 | D5: 252 | E5: 0.151 | F5: =B5/C5 -> 1.1051374 | G5: =B5/D5 -> 7.3412698 | H5: LSE:PETS; FY25A actuals
A6: Chewy Inc (US) | B6: 8200 | C6: 11900 | D6: 280 | E6: 0.024 | F6: =B6/C6 -> 0.68907563 | G6: =B6/D6 -> 29.285714 | H6: CHWY; US pure-play online; lower margins
A7: Zooplus AG (Germany) | B7: 3100 | C7: 2200 | D7: 88 | E7: 0.04 | F7: =B7/C7 -> 1.4090909 | G7: =B7/D7 -> 35.227273 | H7: Acquired by Hellman & Friedman 2022
A8: PetSmart (US, PE-owned) | B8: Private | C8: 7800 | D8: 1050 | E8: 0.135 | F8: n/m | G8: =D8/D8 -> 1 | H8: Private; 2015 BC Partners LBO; ~7x entry
A9: Greggs plc | B9: 2800 | C9: 1980 | D9: 320 | E9: 0.162 | F9: =B9/C9 -> 1.4141414 | G9: =B9/D9 -> 8.75 | H9: UK specialist food retail; margin comp
A10: Next plc | B10: 12500 | C10: 5400 | D10: 1080 | E10: 0.2 | F10: =B10/C10 -> 2.3148148 | G10: =B10/D10 -> 11.574074 | H10: Premium UK retail; operational excellence
A12: Peer Median | B12: — | C12: — | D12: — | E12: — | F12: =MEDIAN(F5,F6,F7,F9,F10) -> 1.4090909 | G12: =MEDIAN(G5,G6,G7,G9,G10) -> 11.574074
A13: Peer Mean | B13: — | C13: — | D13: — | E13: — | F13: =AVERAGE(F5,F6,F7,F9,F10) -> 1.386452 | G13: =AVERAGE(G5,G6,G7,G9,G10) -> 18.435666
A15: Pets at Home (LBO Entry) | B15: =Assumptions!B11 -> 1890 | C15: 1674 | D15: 252 | E15: 0.151 | F15: =B15/C15 -> 1.1290323 | G15: =B15/D15 -> 7.5 | H15: At 7.5x EV/EBITDA entry multiple
A18: Note: EV and estimates from Yahoo Finance / public filings. Private company estimates from press reports. All £m.

Sheet Investment Memo
A1: INVESTMENT MEMO — PETS AT HOME GROUP PLC (LSE: PETS)
A2: Prepared by: Yassin Al-Yassin | Dec 2025 | LBO Analysis | Sponsor: Hypothetical PE Fund
A4: EXECUTIVE SUMMARY
A5: Situation | B5: Pets at Home is the UK's leading pet care specialist, operating 450+ stores and a rapidly scaling Joint Venture veterinary practice network across the UK. The company is FTSE 250-listed with a market cap of ~£1.8bn. This memo analyses a hypothetical take-private LBO at a 7.5x EV/EBITDA entry multiple, implying an enterprise value of ~£1,890m.
A6: Investment Return | B6: Base case analysis implies a 5-year IRR of ~20-22% and MoM of ~2.5-2.8x on a £459m sponsor equity cheque, driven by EBITDA growth, debt paydown via cash sweep, and modest multiple expansion from 7.5x to 8.0x at exit.
A8: COMPANY OVERVIEW
A9: Business Model | B9: Pets at Home operates across three segments: (1) Retail, UK's largest pet supplies retailer by market share; (2) Vet Group, 450+ Joint Venture veterinary practices operated with self-employed vets; (3) Subscription Services, Puppy & Kitten Club and VIP loyalty programme with 8m+ members. The vet JV model is capital-light and creates a recurring revenue flywheel.
A10: Financials | B10: FY2025A: Revenue £1,674m (+4.7% YoY), EBITDA £252m (15.1% margin), Net Income £147m. Net cash position (pre-LBO). Capex ~£70m (4.2% of revenue) driven by new store rollout and vet practice fit-outs. Strong FCF conversion; EBITDA - Capex / EBITDA ~72%.
A12: LBO INVESTMENT THESIS
A13: 1. Defensive Cash Flows | B13: Pet care is a counter-cyclical category, UK pet ownership rose 12% during 2020-22 and ownership rates remain elevated. Recurring spend on food, medication, and vet services provides visibility. Pets at Home has not reported a revenue decline in 10+ years.
A14: 2. Vet Network Maturation | B14: The JV vet practices are in early maturity, 450+ sites, growing EBITDA contribution, and high customer lifetime value. As practices mature, margins expand without incremental capex. This is the core value creation driver.
A15: 3. Loyalty & Data Moat | B15: 8m+ VIP loyalty members represent a significant CRM and data asset. Subscription revenue streams (Puppy & Kitten Club) drive repeat purchases and reduce churn. Hard to replicate by pure-play e-commerce competitors.
A16: 4. Debt Paydown | B16: The business generates ~£180m+ annual FCF at entry. At 50% cash sweep, ~£90m+ per year is applied to TLA amortisation. This rapidly deleverages the capital structure, estimated from ~3.7x to <2.0x Net Debt / EBITDA by Year 5.
A17: 5. Exit Optionality | B17: Multiple exit routes: re-IPO (Pets@Home has been public before and has investor familiarity), trade sale to US strategic (Chewy, PetSmart), or secondary PE buyout. Public market re-rating on vet practice profitability is a realistic catalyst.
A19: KEY RISKS
A20: Leverage Risk | B20: Entry leverage of 3.7x Debt/EBITDA (blended) is moderate for a defensive business but leaves limited headroom for an EBITDA miss. A 10% EBITDA decline would push leverage toward 4.1x, still serviceable but covenant pressure likely.
A21: Vet JV Execution | B21: JV vet model depends on self-employed vets choosing Pets at Home. Attrition or competition from CVS Group / IVC Evidensia for veterinary talent could slow practice revenue growth.
A22: E-commerce Competition | B22: Zooplus, Chewy (US) and Amazon continue to pressure retail margins on consumables. Pets at Home's in-store experience, grooming, and vet services are partially defensive but not immune.
A23: Regulatory / Macro | B23: Rising National Living Wage increases staff costs (~15% of revenue). Any change to veterinary regulation or JV structure could impair the vet segment valuation.
A25: VALUATION
A26: Entry | B26: 7.5x LTM EBITDA (£252m) = £1,890m EV. In line with UK specialist retail LBO precedents. Represents a ~2% premium to current market EV of ~£1,850m (take-private premium).
A27: Exit | B27: 8.0x exit EV/EBITDA applied to FY2030E EBITDA. Conservative vs. peer median. If vet practices are separately valued at a healthcare multiple (~12-15x), blended exit multiple could be higher.
A28: Returns | B28: Base case: ~20-22% IRR, ~2.5-2.8x MoM on 5yr hold. Sensitivity analysis shows IRR remains >15% across a wide range of entry/exit multiples (see Sensitivity tab).
A30: DATA SOURCES
A31: Sources | B31: Pets at Home FY2024 & FY2025 Annual Reports | LSE RNS announcements | Yahoo Finance (share price, peer data) | Hellman & Friedman / Zooplus deal press releases | CVS Group / IVC Evidensia investor materials | UK Petfood Manufacturers Association market data
